2021-08-09 13:26:16,955 ERROR: Exception on /api/users [POST] [in c:\users\fb\appdata\local\programs\python\python37\lib\site-packages\flask\app.py:1455]
Traceback (most recent call last):
  File "c:\users\fb\appdata\local\programs\python\python37\lib\site-packages\sqlalchemy\engine\base.py", line 1772, in _execute_context
    cursor, statement, parameters, context
  File "c:\users\fb\appdata\local\programs\python\python37\lib\site-packages\sqlalchemy\engine\default.py", line 717, in do_execute
    cursor.execute(statement, parameters)
  File "c:\users\fb\appdata\local\programs\python\python37\lib\site-packages\pymysql\cursors.py", line 148, in execute
    result = self._query(query)
  File "c:\users\fb\appdata\local\programs\python\python37\lib\site-packages\pymysql\cursors.py", line 310, in _query
    conn.query(q)
  File "c:\users\fb\appdata\local\programs\python\python37\lib\site-packages\pymysql\connections.py", line 548, in query
    self._affected_rows = self._read_query_result(unbuffered=unbuffered)
  File "c:\users\fb\appdata\local\programs\python\python37\lib\site-packages\pymysql\connections.py", line 775, in _read_query_result
    result.read()
  File "c:\users\fb\appdata\local\programs\python\python37\lib\site-packages\pymysql\connections.py", line 1156, in read
    first_packet = self.connection._read_packet()
  File "c:\users\fb\appdata\local\programs\python\python37\lib\site-packages\pymysql\connections.py", line 725, in _read_packet
    packet.raise_for_error()
  File "c:\users\fb\appdata\local\programs\python\python37\lib\site-packages\pymysql\protocol.py", line 221, in raise_for_error
    err.raise_mysql_exception(self._data)
  File "c:\users\fb\appdata\local\programs\python\python37\lib\site-packages\pymysql\err.py", line 143, in raise_mysql_exception
    raise errorclass(errno, errval)
pymysql.err.IntegrityError: (1062, "Duplicate entry 'hjzjzbsjdj@gmail.com' for key 'user.ix_user_email'")

The above exception was the direct cause of the following exception:

Traceback (most recent call last):
  File "c:\users\fb\appdata\local\programs\python\python37\lib\site-packages\flask\app.py", line 2070, in wsgi_app
    response = self.full_dispatch_request()
  File "c:\users\fb\appdata\local\programs\python\python37\lib\site-packages\flask\app.py", line 1515, in full_dispatch_request
    rv = self.handle_user_exception(e)
  File "c:\users\fb\appdata\local\programs\python\python37\lib\site-packages\flask\app.py", line 1513, in full_dispatch_request
    rv = self.dispatch_request()
  File "c:\users\fb\appdata\local\programs\python\python37\lib\site-packages\flask\app.py", line 1499, in dispatch_request
    return self.ensure_sync(self.view_functions[rule.endpoint])(**req.view_args)
  File "C:\xampp\htdocs\onely\app\api\users.py", line 164, in create_user
    db.session.commit()
  File "<string>", line 2, in commit
  File "c:\users\fb\appdata\local\programs\python\python37\lib\site-packages\sqlalchemy\orm\session.py", line 1428, in commit
    self._transaction.commit(_to_root=self.future)
  File "c:\users\fb\appdata\local\programs\python\python37\lib\site-packages\sqlalchemy\orm\session.py", line 829, in commit
    self._prepare_impl()
  File "c:\users\fb\appdata\local\programs\python\python37\lib\site-packages\sqlalchemy\orm\session.py", line 808, in _prepare_impl
    self.session.flush()
  File "c:\users\fb\appdata\local\programs\python\python37\lib\site-packages\sqlalchemy\orm\session.py", line 3298, in flush
    self._flush(objects)
  File "c:\users\fb\appdata\local\programs\python\python37\lib\site-packages\sqlalchemy\orm\session.py", line 3438, in _flush
    transaction.rollback(_capture_exception=True)
  File "c:\users\fb\appdata\local\programs\python\python37\lib\site-packages\sqlalchemy\util\langhelpers.py", line 72, in __exit__
    with_traceback=exc_tb,
  File "c:\users\fb\appdata\local\programs\python\python37\lib\site-packages\sqlalchemy\util\compat.py", line 207, in raise_
    raise exception
  File "c:\users\fb\appdata\local\programs\python\python37\lib\site-packages\sqlalchemy\orm\session.py", line 3398, in _flush
    flush_context.execute()
  File "c:\users\fb\appdata\local\programs\python\python37\lib\site-packages\sqlalchemy\orm\unitofwork.py", line 456, in execute
    rec.execute(self)
  File "c:\users\fb\appdata\local\programs\python\python37\lib\site-packages\sqlalchemy\orm\unitofwork.py", line 633, in execute
    uow,
  File "c:\users\fb\appdata\local\programs\python\python37\lib\site-packages\sqlalchemy\orm\persistence.py", line 247, in save_obj
    insert,
  File "c:\users\fb\appdata\local\programs\python\python37\lib\site-packages\sqlalchemy\orm\persistence.py", line 1222, in _emit_insert_statements
    execution_options=execution_options,
  File "c:\users\fb\appdata\local\programs\python\python37\lib\site-packages\sqlalchemy\engine\base.py", line 1583, in _execute_20
    return meth(self, args_10style, kwargs_10style, execution_options)
  File "c:\users\fb\appdata\local\programs\python\python37\lib\site-packages\sqlalchemy\sql\elements.py", line 324, in _execute_on_connection
    self, multiparams, params, execution_options
  File "c:\users\fb\appdata\local\programs\python\python37\lib\site-packages\sqlalchemy\engine\base.py", line 1462, in _execute_clauseelement
    cache_hit=cache_hit,
  File "c:\users\fb\appdata\local\programs\python\python37\lib\site-packages\sqlalchemy\engine\base.py", line 1815, in _execute_context
    e, statement, parameters, cursor, context
  File "c:\users\fb\appdata\local\programs\python\python37\lib\site-packages\sqlalchemy\engine\base.py", line 1996, in _handle_dbapi_exception
    sqlalchemy_exception, with_traceback=exc_info[2], from_=e
  File "c:\users\fb\appdata\local\programs\python\python37\lib\site-packages\sqlalchemy\util\compat.py", line 207, in raise_
    raise exception
  File "c:\users\fb\appdata\local\programs\python\python37\lib\site-packages\sqlalchemy\engine\base.py", line 1772, in _execute_context
    cursor, statement, parameters, context
  File "c:\users\fb\appdata\local\programs\python\python37\lib\site-packages\sqlalchemy\engine\default.py", line 717, in do_execute
    cursor.execute(statement, parameters)
  File "c:\users\fb\appdata\local\programs\python\python37\lib\site-packages\pymysql\cursors.py", line 148, in execute
    result = self._query(query)
  File "c:\users\fb\appdata\local\programs\python\python37\lib\site-packages\pymysql\cursors.py", line 310, in _query
    conn.query(q)
  File "c:\users\fb\appdata\local\programs\python\python37\lib\site-packages\pymysql\connections.py", line 548, in query
    self._affected_rows = self._read_query_result(unbuffered=unbuffered)
  File "c:\users\fb\appdata\local\programs\python\python37\lib\site-packages\pymysql\connections.py", line 775, in _read_query_result
    result.read()
  File "c:\users\fb\appdata\local\programs\python\python37\lib\site-packages\pymysql\connections.py", line 1156, in read
    first_packet = self.connection._read_packet()
  File "c:\users\fb\appdata\local\programs\python\python37\lib\site-packages\pymysql\connections.py", line 725, in _read_packet
    packet.raise_for_error()
  File "c:\users\fb\appdata\local\programs\python\python37\lib\site-packages\pymysql\protocol.py", line 221, in raise_for_error
    err.raise_mysql_exception(self._data)
  File "c:\users\fb\appdata\local\programs\python\python37\lib\site-packages\pymysql\err.py", line 143, in raise_mysql_exception
    raise errorclass(errno, errval)
sqlalchemy.exc.IntegrityError: (pymysql.err.IntegrityError) (1062, "Duplicate entry 'hjzjzbsjdj@gmail.com' for key 'user.ix_user_email'")
[SQL: INSERT INTO user (username, name, email, country, phone_number, birthday, gender, looking_for, genres, artists, questions, anthem, bio, location, discover_location, height, hometown, ethnicity, job, education, religion, company, instagram, password_hash, avatar, photo1, photo2, photo3, photo4, photo5, photo6, `favoriteSongs`, `favoriteAlbums`, `favoritePlaylists`, `favoriteArtists`, `favoriteGenres`, verification_code, verified, last_seen, creation_date, token, token_expiration) VALUES (%(username)s, %(name)s, %(email)s, %(country)s, %(phone_number)s, %(birthday)s, %(gender)s, %(looking_for)s, %(genres)s, %(artists)s, %(questions)s, %(anthem)s, %(bio)s, %(location)s, %(discover_location)s, %(height)s, %(hometown)s, %(ethnicity)s, %(job)s, %(education)s, %(religion)s, %(company)s, %(instagram)s, %(password_hash)s, %(avatar)s, %(photo1)s, %(photo2)s, %(photo3)s, %(photo4)s, %(photo5)s, %(photo6)s, %(favoriteSongs)s, %(favoriteAlbums)s, %(favoritePlaylists)s, %(favoriteArtists)s, %(favoriteGenres)s, %(verification_code)s, %(verified)s, %(last_seen)s, %(creation_date)s, %(token)s, %(token_expiration)s)]
[parameters: {'username': 'hshsbsbsb', 'name': 'hsisjsnsn', 'email': 'hjzjzbsjdj@gmail.com', 'country': None, 'phone_number': None, 'birthday': None, 'gender': None, 'looking_for': None, 'genres': None, 'artists': None, 'questions': None, 'anthem': None, 'bio': None, 'location': None, 'discover_location': None, 'height': None, 'hometown': None, 'ethnicity': None, 'job': None, 'education': None, 'religion': None, 'company': None, 'instagram': None, 'password_hash': 'pbkdf2:sha256:260000$nP0LeveTo2vtyRBv$dd48d869e8034f4a096d68c8f59f52b3a1c3d4f19f3ed02fb27b30f74e8a5515', 'avatar': None, 'photo1': None, 'photo2': None, 'photo3': None, 'photo4': None, 'photo5': None, 'photo6': None, 'favoriteSongs': None, 'favoriteAlbums': None, 'favoritePlaylists': None, 'favoriteArtists': None, 'favoriteGenres': None, 'verification_code': 6440, 'verified': 0, 'last_seen': datetime.datetime(2021, 8, 9, 8, 26, 16, 462915), 'creation_date': datetime.datetime(2021, 8, 9, 8, 26, 16, 462915), 'token': None, 'token_expiration': None}]
(Background on this error at: https://sqlalche.me/e/14/gkpj)
2021-08-09 16:10:55,257 INFO: Strefi startup [in C:\xampp\htdocs\onely\app\__init__.py:90]
2021-08-09 16:11:03,198 INFO: Strefi startup [in C:\xampp\htdocs\onely\app\__init__.py:90]
2021-08-10 14:10:48,430 INFO: Strefi startup [in C:\xampp\htdocs\onely\app\__init__.py:90]
