2021-09-28 16:54:12,104 ERROR: Exception on /liverequests [GET] [in c:\users\fb\appdata\local\programs\python\python37\lib\site-packages\flask\app.py:1455]
Traceback (most recent call last):
  File "c:\users\fb\appdata\local\programs\python\python37\lib\site-packages\flask\app.py", line 2070, in wsgi_app
    response = self.full_dispatch_request()
  File "c:\users\fb\appdata\local\programs\python\python37\lib\site-packages\flask\app.py", line 1515, in full_dispatch_request
    rv = self.handle_user_exception(e)
  File "c:\users\fb\appdata\local\programs\python\python37\lib\site-packages\flask\app.py", line 1513, in full_dispatch_request
    rv = self.dispatch_request()
  File "c:\users\fb\appdata\local\programs\python\python37\lib\site-packages\flask\app.py", line 1499, in dispatch_request
    return self.ensure_sync(self.view_functions[rule.endpoint])(**req.view_args)
  File "C:\xampp\htdocs\onely\app\main\routes.py", line 49, in liverequests
    return render_template('liverequests.html', all_requests=all_requests)
  File "c:\users\fb\appdata\local\programs\python\python37\lib\site-packages\flask\templating.py", line 150, in render_template
    ctx.app,
  File "c:\users\fb\appdata\local\programs\python\python37\lib\site-packages\flask\templating.py", line 128, in _render
    rv = template.render(context)
  File "c:\users\fb\appdata\local\programs\python\python37\lib\site-packages\jinja2\environment.py", line 1304, in render
    self.environment.handle_exception()
  File "c:\users\fb\appdata\local\programs\python\python37\lib\site-packages\jinja2\environment.py", line 925, in handle_exception
    raise rewrite_traceback_stack(source=source)
  File "C:\xampp\htdocs\onely\app\templates\liverequests.html", line 42, in top-level template code
    <!--        <td>{{user.photo}}</td>-->
  File "c:\users\fb\appdata\local\programs\python\python37\lib\site-packages\jinja2\environment.py", line 474, in getattr
    return getattr(obj, attribute)
jinja2.exceptions.UndefinedError: 'user' is undefined
2021-09-28 16:55:18,726 INFO: Strefi startup [in C:\xampp\htdocs\onely\app\__init__.py:90]
2021-09-28 16:55:42,429 INFO: Strefi startup [in C:\xampp\htdocs\onely\app\__init__.py:90]
2021-09-28 16:56:24,757 INFO: Strefi startup [in C:\xampp\htdocs\onely\app\__init__.py:90]
2021-09-28 16:57:01,652 INFO: Strefi startup [in C:\xampp\htdocs\onely\app\__init__.py:90]
2021-09-29 09:49:10,850 INFO: Strefi startup [in C:\xampp\htdocs\onely\app\__init__.py:90]
2021-09-29 09:49:59,048 INFO: Strefi startup [in C:\xampp\htdocs\onely\app\__init__.py:90]
2021-09-29 09:50:14,016 INFO: Strefi startup [in C:\xampp\htdocs\onely\app\__init__.py:90]
2021-09-29 10:30:31,421 INFO: Strefi startup [in C:\xampp\htdocs\onely\app\__init__.py:90]
2021-09-29 10:31:00,122 INFO: Strefi startup [in C:\xampp\htdocs\onely\app\__init__.py:90]
2021-09-29 10:31:21,062 INFO: Strefi startup [in C:\xampp\htdocs\onely\app\__init__.py:90]
2021-09-29 10:36:33,974 INFO: Strefi startup [in C:\xampp\htdocs\onely\app\__init__.py:90]
2021-09-29 10:36:34,161 ERROR: Exception on /liverequests [GET] [in c:\users\fb\appdata\local\programs\python\python37\lib\site-packages\flask\app.py:1455]
Traceback (most recent call last):
  File "c:\users\fb\appdata\local\programs\python\python37\lib\site-packages\flask\app.py", line 2070, in wsgi_app
    response = self.full_dispatch_request()
  File "c:\users\fb\appdata\local\programs\python\python37\lib\site-packages\flask\app.py", line 1515, in full_dispatch_request
    rv = self.handle_user_exception(e)
  File "c:\users\fb\appdata\local\programs\python\python37\lib\site-packages\flask\app.py", line 1513, in full_dispatch_request
    rv = self.dispatch_request()
  File "c:\users\fb\appdata\local\programs\python\python37\lib\site-packages\flask\app.py", line 1499, in dispatch_request
    return self.ensure_sync(self.view_functions[rule.endpoint])(**req.view_args)
  File "C:\xampp\htdocs\onely\app\main\routes.py", line 52, in liverequests
    return render_template('liverequests.html', all_requests=all_requestss)
  File "c:\users\fb\appdata\local\programs\python\python37\lib\site-packages\flask\templating.py", line 148, in render_template
    ctx.app.jinja_env.get_or_select_template(template_name_or_list),
  File "c:\users\fb\appdata\local\programs\python\python37\lib\site-packages\jinja2\environment.py", line 1068, in get_or_select_template
    return self.get_template(template_name_or_list, parent, globals)
  File "c:\users\fb\appdata\local\programs\python\python37\lib\site-packages\jinja2\environment.py", line 997, in get_template
    return self._load_template(name, globals)
  File "c:\users\fb\appdata\local\programs\python\python37\lib\site-packages\jinja2\environment.py", line 958, in _load_template
    template = self.loader.load(self, name, self.make_globals(globals))
  File "c:\users\fb\appdata\local\programs\python\python37\lib\site-packages\jinja2\loaders.py", line 137, in load
    code = environment.compile(source, name, filename)
  File "c:\users\fb\appdata\local\programs\python\python37\lib\site-packages\jinja2\environment.py", line 757, in compile
    self.handle_exception(source=source_hint)
  File "c:\users\fb\appdata\local\programs\python\python37\lib\site-packages\jinja2\environment.py", line 925, in handle_exception
    raise rewrite_traceback_stack(source=source)
  File "C:\xampp\htdocs\onely\app\templates\liverequests.html", line 46, in template
    {% endfor %}
jinja2.exceptions.TemplateSyntaxError: Encountered unknown tag 'endfor'. You probably made a nesting mistake. Jinja is expecting this tag, but currently looking for 'endif'. The innermost block that needs to be closed is 'if'.
2021-09-29 10:36:59,789 INFO: Strefi startup [in C:\xampp\htdocs\onely\app\__init__.py:90]
2021-09-29 10:38:54,044 INFO: Strefi startup [in C:\xampp\htdocs\onely\app\__init__.py:90]
2021-09-29 10:39:25,271 INFO: Strefi startup [in C:\xampp\htdocs\onely\app\__init__.py:90]
2021-09-29 10:39:49,229 INFO: Strefi startup [in C:\xampp\htdocs\onely\app\__init__.py:90]
2021-09-29 10:48:47,941 INFO: Strefi startup [in C:\xampp\htdocs\onely\app\__init__.py:90]
2021-09-29 10:49:35,226 ERROR: Exception on /approveRequest/146 [GET] [in c:\users\fb\appdata\local\programs\python\python37\lib\site-packages\flask\app.py:1455]
Traceback (most recent call last):
  File "c:\users\fb\appdata\local\programs\python\python37\lib\site-packages\flask\app.py", line 2070, in wsgi_app
    response = self.full_dispatch_request()
  File "c:\users\fb\appdata\local\programs\python\python37\lib\site-packages\flask\app.py", line 1515, in full_dispatch_request
    rv = self.handle_user_exception(e)
  File "c:\users\fb\appdata\local\programs\python\python37\lib\site-packages\flask\app.py", line 1513, in full_dispatch_request
    rv = self.dispatch_request()
  File "c:\users\fb\appdata\local\programs\python\python37\lib\site-packages\flask\app.py", line 1499, in dispatch_request
    return self.ensure_sync(self.view_functions[rule.endpoint])(**req.view_args)
TypeError: approveRequest() got an unexpected keyword argument 'userid'
2021-09-29 10:50:23,471 INFO: Strefi startup [in C:\xampp\htdocs\onely\app\__init__.py:90]
2021-09-29 10:50:30,140 ERROR: Exception on /approveRequest/146 [GET] [in c:\users\fb\appdata\local\programs\python\python37\lib\site-packages\flask\app.py:1455]
Traceback (most recent call last):
  File "c:\users\fb\appdata\local\programs\python\python37\lib\site-packages\flask\app.py", line 2070, in wsgi_app
    response = self.full_dispatch_request()
  File "c:\users\fb\appdata\local\programs\python\python37\lib\site-packages\flask\app.py", line 1515, in full_dispatch_request
    rv = self.handle_user_exception(e)
  File "c:\users\fb\appdata\local\programs\python\python37\lib\site-packages\flask\app.py", line 1513, in full_dispatch_request
    rv = self.dispatch_request()
  File "c:\users\fb\appdata\local\programs\python\python37\lib\site-packages\flask\app.py", line 1499, in dispatch_request
    return self.ensure_sync(self.view_functions[rule.endpoint])(**req.view_args)
TypeError: approveRequest() got an unexpected keyword argument 'userid'
2021-09-29 10:50:43,687 INFO: Strefi startup [in C:\xampp\htdocs\onely\app\__init__.py:90]
2021-09-29 10:50:47,609 ERROR: Exception on /approveRequest/146 [GET] [in c:\users\fb\appdata\local\programs\python\python37\lib\site-packages\flask\app.py:1455]
Traceback (most recent call last):
  File "c:\users\fb\appdata\local\programs\python\python37\lib\site-packages\flask\app.py", line 2070, in wsgi_app
    response = self.full_dispatch_request()
  File "c:\users\fb\appdata\local\programs\python\python37\lib\site-packages\flask\app.py", line 1515, in full_dispatch_request
    rv = self.handle_user_exception(e)
  File "c:\users\fb\appdata\local\programs\python\python37\lib\site-packages\flask\app.py", line 1513, in full_dispatch_request
    rv = self.dispatch_request()
  File "c:\users\fb\appdata\local\programs\python\python37\lib\site-packages\flask\app.py", line 1499, in dispatch_request
    return self.ensure_sync(self.view_functions[rule.endpoint])(**req.view_args)
TypeError: approveRequest() got an unexpected keyword argument 'userid'
2021-09-29 10:51:12,781 INFO: Strefi startup [in C:\xampp\htdocs\onely\app\__init__.py:90]
2021-09-29 10:53:36,767 INFO: Strefi startup [in C:\xampp\htdocs\onely\app\__init__.py:90]
