2021-09-28 09:09:02,293 ERROR: Exception on /api/cdn/null [GET] [in c:\users\fb\appdata\local\programs\python\python37\lib\site-packages\flask\app.py:1455]
Traceback (most recent call last):
  File "c:\users\fb\appdata\local\programs\python\python37\lib\site-packages\flask\app.py", line 2070, in wsgi_app
    response = self.full_dispatch_request()
  File "c:\users\fb\appdata\local\programs\python\python37\lib\site-packages\flask\app.py", line 1515, in full_dispatch_request
    rv = self.handle_user_exception(e)
  File "c:\users\fb\appdata\local\programs\python\python37\lib\site-packages\flask\app.py", line 1513, in full_dispatch_request
    rv = self.dispatch_request()
  File "c:\users\fb\appdata\local\programs\python\python37\lib\site-packages\flask\app.py", line 1499, in dispatch_request
    return self.ensure_sync(self.view_functions[rule.endpoint])(**req.view_args)
  File "C:\xampp\htdocs\onely\app\api\cdn.py", line 23, in get_file
    s3_object.download_fileobj(a_file)
  File "c:\users\fb\appdata\local\programs\python\python37\lib\site-packages\boto3\s3\inject.py", line 761, in object_download_fileobj
    ExtraArgs=ExtraArgs, Callback=Callback, Config=Config)
  File "c:\users\fb\appdata\local\programs\python\python37\lib\site-packages\boto3\s3\inject.py", line 679, in download_fileobj
    return future.result()
  File "c:\users\fb\appdata\local\programs\python\python37\lib\site-packages\s3transfer\futures.py", line 106, in result
    return self._coordinator.result()
  File "c:\users\fb\appdata\local\programs\python\python37\lib\site-packages\s3transfer\futures.py", line 265, in result
    raise self._exception
  File "c:\users\fb\appdata\local\programs\python\python37\lib\site-packages\s3transfer\tasks.py", line 255, in _main
    self._submit(transfer_future=transfer_future, **kwargs)
  File "c:\users\fb\appdata\local\programs\python\python37\lib\site-packages\s3transfer\download.py", line 343, in _submit
    **transfer_future.meta.call_args.extra_args
  File "c:\users\fb\appdata\local\programs\python\python37\lib\site-packages\botocore\client.py", line 386, in _api_call
    return self._make_api_call(operation_name, kwargs)
  File "c:\users\fb\appdata\local\programs\python\python37\lib\site-packages\botocore\client.py", line 705, in _make_api_call
    raise error_class(parsed_response, operation_name)
botocore.exceptions.ClientError: An error occurred (404) when calling the HeadObject operation: Not Found
2021-09-28 09:09:02,774 ERROR: Exception on /api/cdn/null [GET] [in c:\users\fb\appdata\local\programs\python\python37\lib\site-packages\flask\app.py:1455]
Traceback (most recent call last):
  File "c:\users\fb\appdata\local\programs\python\python37\lib\site-packages\flask\app.py", line 2070, in wsgi_app
    response = self.full_dispatch_request()
  File "c:\users\fb\appdata\local\programs\python\python37\lib\site-packages\flask\app.py", line 1515, in full_dispatch_request
    rv = self.handle_user_exception(e)
  File "c:\users\fb\appdata\local\programs\python\python37\lib\site-packages\flask\app.py", line 1513, in full_dispatch_request
    rv = self.dispatch_request()
  File "c:\users\fb\appdata\local\programs\python\python37\lib\site-packages\flask\app.py", line 1499, in dispatch_request
    return self.ensure_sync(self.view_functions[rule.endpoint])(**req.view_args)
  File "C:\xampp\htdocs\onely\app\api\cdn.py", line 23, in get_file
    s3_object.download_fileobj(a_file)
  File "c:\users\fb\appdata\local\programs\python\python37\lib\site-packages\boto3\s3\inject.py", line 761, in object_download_fileobj
    ExtraArgs=ExtraArgs, Callback=Callback, Config=Config)
  File "c:\users\fb\appdata\local\programs\python\python37\lib\site-packages\boto3\s3\inject.py", line 679, in download_fileobj
    return future.result()
  File "c:\users\fb\appdata\local\programs\python\python37\lib\site-packages\s3transfer\futures.py", line 106, in result
    return self._coordinator.result()
  File "c:\users\fb\appdata\local\programs\python\python37\lib\site-packages\s3transfer\futures.py", line 265, in result
    raise self._exception
  File "c:\users\fb\appdata\local\programs\python\python37\lib\site-packages\s3transfer\tasks.py", line 255, in _main
    self._submit(transfer_future=transfer_future, **kwargs)
  File "c:\users\fb\appdata\local\programs\python\python37\lib\site-packages\s3transfer\download.py", line 343, in _submit
    **transfer_future.meta.call_args.extra_args
  File "c:\users\fb\appdata\local\programs\python\python37\lib\site-packages\botocore\client.py", line 386, in _api_call
    return self._make_api_call(operation_name, kwargs)
  File "c:\users\fb\appdata\local\programs\python\python37\lib\site-packages\botocore\client.py", line 705, in _make_api_call
    raise error_class(parsed_response, operation_name)
botocore.exceptions.ClientError: An error occurred (404) when calling the HeadObject operation: Not Found
2021-09-28 09:09:04,797 ERROR: Exception on /api/cdn/null [GET] [in c:\users\fb\appdata\local\programs\python\python37\lib\site-packages\flask\app.py:1455]
Traceback (most recent call last):
  File "c:\users\fb\appdata\local\programs\python\python37\lib\site-packages\flask\app.py", line 2070, in wsgi_app
    response = self.full_dispatch_request()
  File "c:\users\fb\appdata\local\programs\python\python37\lib\site-packages\flask\app.py", line 1515, in full_dispatch_request
    rv = self.handle_user_exception(e)
  File "c:\users\fb\appdata\local\programs\python\python37\lib\site-packages\flask\app.py", line 1513, in full_dispatch_request
    rv = self.dispatch_request()
  File "c:\users\fb\appdata\local\programs\python\python37\lib\site-packages\flask\app.py", line 1499, in dispatch_request
    return self.ensure_sync(self.view_functions[rule.endpoint])(**req.view_args)
  File "C:\xampp\htdocs\onely\app\api\cdn.py", line 23, in get_file
    s3_object.download_fileobj(a_file)
  File "c:\users\fb\appdata\local\programs\python\python37\lib\site-packages\boto3\s3\inject.py", line 761, in object_download_fileobj
    ExtraArgs=ExtraArgs, Callback=Callback, Config=Config)
  File "c:\users\fb\appdata\local\programs\python\python37\lib\site-packages\boto3\s3\inject.py", line 679, in download_fileobj
    return future.result()
  File "c:\users\fb\appdata\local\programs\python\python37\lib\site-packages\s3transfer\futures.py", line 106, in result
    return self._coordinator.result()
  File "c:\users\fb\appdata\local\programs\python\python37\lib\site-packages\s3transfer\futures.py", line 265, in result
    raise self._exception
  File "c:\users\fb\appdata\local\programs\python\python37\lib\site-packages\s3transfer\tasks.py", line 255, in _main
    self._submit(transfer_future=transfer_future, **kwargs)
  File "c:\users\fb\appdata\local\programs\python\python37\lib\site-packages\s3transfer\download.py", line 343, in _submit
    **transfer_future.meta.call_args.extra_args
  File "c:\users\fb\appdata\local\programs\python\python37\lib\site-packages\botocore\client.py", line 386, in _api_call
    return self._make_api_call(operation_name, kwargs)
  File "c:\users\fb\appdata\local\programs\python\python37\lib\site-packages\botocore\client.py", line 705, in _make_api_call
    raise error_class(parsed_response, operation_name)
botocore.exceptions.ClientError: An error occurred (404) when calling the HeadObject operation: Not Found
2021-09-28 09:09:14,909 ERROR: Exception on /api/cdn/null [GET] [in c:\users\fb\appdata\local\programs\python\python37\lib\site-packages\flask\app.py:1455]
Traceback (most recent call last):
  File "c:\users\fb\appdata\local\programs\python\python37\lib\site-packages\flask\app.py", line 2070, in wsgi_app
    response = self.full_dispatch_request()
  File "c:\users\fb\appdata\local\programs\python\python37\lib\site-packages\flask\app.py", line 1515, in full_dispatch_request
    rv = self.handle_user_exception(e)
  File "c:\users\fb\appdata\local\programs\python\python37\lib\site-packages\flask\app.py", line 1513, in full_dispatch_request
    rv = self.dispatch_request()
  File "c:\users\fb\appdata\local\programs\python\python37\lib\site-packages\flask\app.py", line 1499, in dispatch_request
    return self.ensure_sync(self.view_functions[rule.endpoint])(**req.view_args)
  File "C:\xampp\htdocs\onely\app\api\cdn.py", line 23, in get_file
    s3_object.download_fileobj(a_file)
  File "c:\users\fb\appdata\local\programs\python\python37\lib\site-packages\boto3\s3\inject.py", line 761, in object_download_fileobj
    ExtraArgs=ExtraArgs, Callback=Callback, Config=Config)
  File "c:\users\fb\appdata\local\programs\python\python37\lib\site-packages\boto3\s3\inject.py", line 679, in download_fileobj
    return future.result()
  File "c:\users\fb\appdata\local\programs\python\python37\lib\site-packages\s3transfer\futures.py", line 106, in result
    return self._coordinator.result()
  File "c:\users\fb\appdata\local\programs\python\python37\lib\site-packages\s3transfer\futures.py", line 265, in result
    raise self._exception
  File "c:\users\fb\appdata\local\programs\python\python37\lib\site-packages\s3transfer\tasks.py", line 255, in _main
    self._submit(transfer_future=transfer_future, **kwargs)
  File "c:\users\fb\appdata\local\programs\python\python37\lib\site-packages\s3transfer\download.py", line 343, in _submit
    **transfer_future.meta.call_args.extra_args
  File "c:\users\fb\appdata\local\programs\python\python37\lib\site-packages\botocore\client.py", line 386, in _api_call
    return self._make_api_call(operation_name, kwargs)
  File "c:\users\fb\appdata\local\programs\python\python37\lib\site-packages\botocore\client.py", line 705, in _make_api_call
    raise error_class(parsed_response, operation_name)
botocore.exceptions.ClientError: An error occurred (404) when calling the HeadObject operation: Not Found
