2021-08-10 15:47:28,522 ERROR: Exception on /api/countries [GET] [in c:\users\fb\appdata\local\programs\python\python37\lib\site-packages\flask\app.py:1455]
Traceback (most recent call last):
  File "c:\users\fb\appdata\local\programs\python\python37\lib\site-packages\flask\app.py", line 2070, in wsgi_app
    response = self.full_dispatch_request()
  File "c:\users\fb\appdata\local\programs\python\python37\lib\site-packages\flask\app.py", line 1515, in full_dispatch_request
    rv = self.handle_user_exception(e)
  File "c:\users\fb\appdata\local\programs\python\python37\lib\site-packages\flask\app.py", line 1513, in full_dispatch_request
    rv = self.dispatch_request()
  File "c:\users\fb\appdata\local\programs\python\python37\lib\site-packages\flask\app.py", line 1499, in dispatch_request
    return self.ensure_sync(self.view_functions[rule.endpoint])(**req.view_args)
  File "C:\xampp\htdocs\onely\app\api\countries.py", line 17, in get_countries
    return jsonify({"key":countyies})
  File "c:\users\fb\appdata\local\programs\python\python37\lib\site-packages\flask\json\__init__.py", line 348, in jsonify
    f"{dumps(data, indent=indent, separators=separators)}\n",
  File "c:\users\fb\appdata\local\programs\python\python37\lib\site-packages\flask\json\__init__.py", line 129, in dumps
    rv = _json.dumps(obj, **kwargs)
  File "c:\users\fb\appdata\local\programs\python\python37\lib\json\__init__.py", line 238, in dumps
    **kw).encode(obj)
  File "c:\users\fb\appdata\local\programs\python\python37\lib\json\encoder.py", line 199, in encode
    chunks = self.iterencode(o, _one_shot=True)
  File "c:\users\fb\appdata\local\programs\python\python37\lib\json\encoder.py", line 257, in iterencode
    return _iterencode(o, 0)
  File "c:\users\fb\appdata\local\programs\python\python37\lib\site-packages\flask\json\__init__.py", line 56, in default
    return super().default(o)
  File "c:\users\fb\appdata\local\programs\python\python37\lib\json\encoder.py", line 179, in default
    raise TypeError(f'Object of type {o.__class__.__name__} '
TypeError: Object of type Countries is not JSON serializable
2021-08-10 15:48:20,137 INFO: Strefi startup [in C:\xampp\htdocs\onely\app\__init__.py:90]
2021-08-10 16:06:09,724 INFO: Strefi startup [in C:\xampp\htdocs\onely\app\__init__.py:90]
2021-08-10 16:07:00,898 INFO: Strefi startup [in C:\xampp\htdocs\onely\app\__init__.py:90]
2021-08-10 16:07:29,863 INFO: Strefi startup [in C:\xampp\htdocs\onely\app\__init__.py:90]
2021-08-11 14:10:11,896 INFO: Strefi startup [in C:\xampp\htdocs\onely\app\__init__.py:90]
2021-08-13 12:29:20,334 INFO: Strefi startup [in C:\xampp\htdocs\onely\app\__init__.py:90]
2021-08-13 12:35:20,139 INFO: Strefi startup [in C:\xampp\htdocs\onely\app\__init__.py:90]
2021-08-13 12:36:40,584 INFO: Strefi startup [in C:\xampp\htdocs\onely\app\__init__.py:90]
2021-08-13 12:40:38,243 INFO: Strefi startup [in C:\xampp\htdocs\onely\app\__init__.py:90]
2021-08-13 12:57:06,071 INFO: Strefi startup [in C:\xampp\htdocs\onely\app\__init__.py:90]
2021-08-13 12:57:23,566 INFO: Strefi startup [in C:\xampp\htdocs\onely\app\__init__.py:90]
2021-08-13 12:57:25,022 ERROR: Exception on /api/sociallogin [POST] [in c:\users\fb\appdata\local\programs\python\python37\lib\site-packages\flask\app.py:1455]
Traceback (most recent call last):
  File "c:\users\fb\appdata\local\programs\python\python37\lib\site-packages\flask\app.py", line 2070, in wsgi_app
    response = self.full_dispatch_request()
  File "c:\users\fb\appdata\local\programs\python\python37\lib\site-packages\flask\app.py", line 1515, in full_dispatch_request
    rv = self.handle_user_exception(e)
  File "c:\users\fb\appdata\local\programs\python\python37\lib\site-packages\flask\app.py", line 1513, in full_dispatch_request
    rv = self.dispatch_request()
  File "c:\users\fb\appdata\local\programs\python\python37\lib\site-packages\flask\app.py", line 1499, in dispatch_request
    return self.ensure_sync(self.view_functions[rule.endpoint])(**req.view_args)
  File "C:\xampp\htdocs\onely\app\api\users.py", line 173, in sociallogin
    user = User.query.filter_by(username=username).first()
NameError: name 'username' is not defined
2021-08-13 12:58:02,571 INFO: Strefi startup [in C:\xampp\htdocs\onely\app\__init__.py:90]
2021-08-13 12:58:04,300 ERROR: Exception on /api/sociallogin [POST] [in c:\users\fb\appdata\local\programs\python\python37\lib\site-packages\flask\app.py:1455]
Traceback (most recent call last):
  File "c:\users\fb\appdata\local\programs\python\python37\lib\site-packages\flask\app.py", line 2070, in wsgi_app
    response = self.full_dispatch_request()
  File "c:\users\fb\appdata\local\programs\python\python37\lib\site-packages\flask\app.py", line 1515, in full_dispatch_request
    rv = self.handle_user_exception(e)
  File "c:\users\fb\appdata\local\programs\python\python37\lib\site-packages\flask\app.py", line 1513, in full_dispatch_request
    rv = self.dispatch_request()
  File "c:\users\fb\appdata\local\programs\python\python37\lib\site-packages\flask\app.py", line 1499, in dispatch_request
    return self.ensure_sync(self.view_functions[rule.endpoint])(**req.view_args)
  File "C:\xampp\htdocs\onely\app\api\users.py", line 173, in sociallogin
    user = User.query.filter_by(username=username).first()
NameError: name 'username' is not defined
2021-08-13 12:59:06,516 INFO: Strefi startup [in C:\xampp\htdocs\onely\app\__init__.py:90]
2021-08-13 12:59:08,531 ERROR: Exception on /api/sociallogin [POST] [in c:\users\fb\appdata\local\programs\python\python37\lib\site-packages\flask\app.py:1455]
Traceback (most recent call last):
  File "c:\users\fb\appdata\local\programs\python\python37\lib\site-packages\flask\app.py", line 2070, in wsgi_app
    response = self.full_dispatch_request()
  File "c:\users\fb\appdata\local\programs\python\python37\lib\site-packages\flask\app.py", line 1516, in full_dispatch_request
    return self.finalize_request(rv)
  File "c:\users\fb\appdata\local\programs\python\python37\lib\site-packages\flask\app.py", line 1535, in finalize_request
    response = self.make_response(rv)
  File "c:\users\fb\appdata\local\programs\python\python37\lib\site-packages\flask\app.py", line 1728, in make_response
    "The view function did not return a valid"
TypeError: The view function did not return a valid response. The return type must be a string, dict, tuple, Response instance, or WSGI callable, but it was a User.
2021-08-13 12:59:27,919 INFO: Strefi startup [in C:\xampp\htdocs\onely\app\__init__.py:90]
2021-08-13 14:49:34,672 ERROR: Exception on /api/sociallogin [POST] [in c:\users\fb\appdata\local\programs\python\python37\lib\site-packages\flask\app.py:1455]
Traceback (most recent call last):
  File "c:\users\fb\appdata\local\programs\python\python37\lib\site-packages\flask\app.py", line 2070, in wsgi_app
    response = self.full_dispatch_request()
  File "c:\users\fb\appdata\local\programs\python\python37\lib\site-packages\flask\app.py", line 1515, in full_dispatch_request
    rv = self.handle_user_exception(e)
  File "c:\users\fb\appdata\local\programs\python\python37\lib\site-packages\flask\app.py", line 1513, in full_dispatch_request
    rv = self.dispatch_request()
  File "c:\users\fb\appdata\local\programs\python\python37\lib\site-packages\flask\app.py", line 1499, in dispatch_request
    return self.ensure_sync(self.view_functions[rule.endpoint])(**req.view_args)
  File "C:\xampp\htdocs\onely\app\api\users.py", line 175, in sociallogin
    return jsonify(user.to_dict())
AttributeError: 'NoneType' object has no attribute 'to_dict'
2021-08-13 14:50:04,548 INFO: Strefi startup [in C:\xampp\htdocs\onely\app\__init__.py:90]
2021-08-13 14:50:12,167 ERROR: Exception on /api/sociallogin [POST] [in c:\users\fb\appdata\local\programs\python\python37\lib\site-packages\flask\app.py:1455]
Traceback (most recent call last):
  File "c:\users\fb\appdata\local\programs\python\python37\lib\site-packages\flask\app.py", line 2070, in wsgi_app
    response = self.full_dispatch_request()
  File "c:\users\fb\appdata\local\programs\python\python37\lib\site-packages\flask\app.py", line 1516, in full_dispatch_request
    return self.finalize_request(rv)
  File "c:\users\fb\appdata\local\programs\python\python37\lib\site-packages\flask\app.py", line 1535, in finalize_request
    response = self.make_response(rv)
  File "c:\users\fb\appdata\local\programs\python\python37\lib\site-packages\flask\app.py", line 1699, in make_response
    f"The view function for {request.endpoint!r} did not"
TypeError: The view function for 'api.sociallogin' did not return a valid response. The function either returned None or ended without a return statement.
2021-08-13 14:52:31,222 INFO: Strefi startup [in C:\xampp\htdocs\onely\app\__init__.py:90]
2021-08-13 14:52:32,756 ERROR: Exception on /api/sociallogin [POST] [in c:\users\fb\appdata\local\programs\python\python37\lib\site-packages\flask\app.py:1455]
Traceback (most recent call last):
  File "C:\xampp\htdocs\onely\app\api\users.py", line 177, in sociallogin
    return jsonify(user.to_dict())
AttributeError: 'NoneType' object has no attribute 'to_dict'

During handling of the above exception, another exception occurred:

Traceback (most recent call last):
  File "c:\users\fb\appdata\local\programs\python\python37\lib\site-packages\flask\app.py", line 2070, in wsgi_app
    response = self.full_dispatch_request()
  File "c:\users\fb\appdata\local\programs\python\python37\lib\site-packages\flask\app.py", line 1515, in full_dispatch_request
    rv = self.handle_user_exception(e)
  File "c:\users\fb\appdata\local\programs\python\python37\lib\site-packages\flask\app.py", line 1513, in full_dispatch_request
    rv = self.dispatch_request()
  File "c:\users\fb\appdata\local\programs\python\python37\lib\site-packages\flask\app.py", line 1499, in dispatch_request
    return self.ensure_sync(self.view_functions[rule.endpoint])(**req.view_args)
  File "C:\xampp\htdocs\onely\app\api\users.py", line 179, in sociallogin
    return nil
NameError: name 'nil' is not defined
