2021-09-28 08:59:04,227 ERROR: Exception on /api/tokens [POST] [in c:\users\fb\appdata\local\programs\python\python37\lib\site-packages\flask\app.py:1455]
Traceback (most recent call last):
  File "c:\users\fb\appdata\local\programs\python\python37\lib\site-packages\sqlalchemy\engine\base.py", line 3212, in _wrap_pool_connect
    return fn()
  File "c:\users\fb\appdata\local\programs\python\python37\lib\site-packages\sqlalchemy\pool\base.py", line 307, in connect
    return _ConnectionFairy._checkout(self)
  File "c:\users\fb\appdata\local\programs\python\python37\lib\site-packages\sqlalchemy\pool\base.py", line 767, in _checkout
    fairy = _ConnectionRecord.checkout(pool)
  File "c:\users\fb\appdata\local\programs\python\python37\lib\site-packages\sqlalchemy\pool\base.py", line 425, in checkout
    rec = pool._do_get()
  File "c:\users\fb\appdata\local\programs\python\python37\lib\site-packages\sqlalchemy\pool\impl.py", line 146, in _do_get
    self._dec_overflow()
  File "c:\users\fb\appdata\local\programs\python\python37\lib\site-packages\sqlalchemy\util\langhelpers.py", line 72, in __exit__
    with_traceback=exc_tb,
  File "c:\users\fb\appdata\local\programs\python\python37\lib\site-packages\sqlalchemy\util\compat.py", line 207, in raise_
    raise exception
  File "c:\users\fb\appdata\local\programs\python\python37\lib\site-packages\sqlalchemy\pool\impl.py", line 143, in _do_get
    return self._create_connection()
  File "c:\users\fb\appdata\local\programs\python\python37\lib\site-packages\sqlalchemy\pool\base.py", line 253, in _create_connection
    return _ConnectionRecord(self)
  File "c:\users\fb\appdata\local\programs\python\python37\lib\site-packages\sqlalchemy\pool\base.py", line 368, in __init__
    self.__connect()
  File "c:\users\fb\appdata\local\programs\python\python37\lib\site-packages\sqlalchemy\pool\base.py", line 611, in __connect
    pool.logger.debug("Error on connect(): %s", e)
  File "c:\users\fb\appdata\local\programs\python\python37\lib\site-packages\sqlalchemy\util\langhelpers.py", line 72, in __exit__
    with_traceback=exc_tb,
  File "c:\users\fb\appdata\local\programs\python\python37\lib\site-packages\sqlalchemy\util\compat.py", line 207, in raise_
    raise exception
  File "c:\users\fb\appdata\local\programs\python\python37\lib\site-packages\sqlalchemy\pool\base.py", line 605, in __connect
    connection = pool._invoke_creator(self)
  File "c:\users\fb\appdata\local\programs\python\python37\lib\site-packages\sqlalchemy\engine\create.py", line 578, in connect
    return dialect.connect(*cargs, **cparams)
  File "c:\users\fb\appdata\local\programs\python\python37\lib\site-packages\sqlalchemy\engine\default.py", line 584, in connect
    return self.dbapi.connect(*cargs, **cparams)
  File "c:\users\fb\appdata\local\programs\python\python37\lib\site-packages\MySQLdb\__init__.py", line 130, in Connect
    return Connection(*args, **kwargs)
  File "c:\users\fb\appdata\local\programs\python\python37\lib\site-packages\MySQLdb\connections.py", line 185, in __init__
    super().__init__(*args, **kwargs2)
MySQLdb._exceptions.OperationalError: (2002, "Can't connect to MySQL server on 'localhost' (10061)")

The above exception was the direct cause of the following exception:

Traceback (most recent call last):
  File "c:\users\fb\appdata\local\programs\python\python37\lib\site-packages\flask\app.py", line 2070, in wsgi_app
    response = self.full_dispatch_request()
  File "c:\users\fb\appdata\local\programs\python\python37\lib\site-packages\flask\app.py", line 1515, in full_dispatch_request
    rv = self.handle_user_exception(e)
  File "c:\users\fb\appdata\local\programs\python\python37\lib\site-packages\flask\app.py", line 1513, in full_dispatch_request
    rv = self.dispatch_request()
  File "c:\users\fb\appdata\local\programs\python\python37\lib\site-packages\flask\app.py", line 1499, in dispatch_request
    return self.ensure_sync(self.view_functions[rule.endpoint])(**req.view_args)
  File "c:\users\fb\appdata\local\programs\python\python37\lib\site-packages\flask_httpauth.py", line 161, in decorated
    user = self.authenticate(auth, password)
  File "c:\users\fb\appdata\local\programs\python\python37\lib\site-packages\flask_httpauth.py", line 238, in authenticate
    return self.verify_password_callback(username, client_password)
  File "C:\xampp\htdocs\onely\app\api\auth.py", line 13, in verify_password
    user = User.query.filter_by(username=username).first()
  File "c:\users\fb\appdata\local\programs\python\python37\lib\site-packages\sqlalchemy\orm\query.py", line 2763, in first
    return self.limit(1)._iter().first()
  File "c:\users\fb\appdata\local\programs\python\python37\lib\site-packages\sqlalchemy\orm\query.py", line 2850, in _iter
    execution_options={"_sa_orm_load_options": self.load_options},
  File "c:\users\fb\appdata\local\programs\python\python37\lib\site-packages\sqlalchemy\orm\session.py", line 1688, in execute
    conn = self._connection_for_bind(bind)
  File "c:\users\fb\appdata\local\programs\python\python37\lib\site-packages\sqlalchemy\orm\session.py", line 1530, in _connection_for_bind
    engine, execution_options
  File "c:\users\fb\appdata\local\programs\python\python37\lib\site-packages\sqlalchemy\orm\session.py", line 747, in _connection_for_bind
    conn = bind.connect()
  File "c:\users\fb\appdata\local\programs\python\python37\lib\site-packages\sqlalchemy\engine\base.py", line 3166, in connect
    return self._connection_cls(self, close_with_result=close_with_result)
  File "c:\users\fb\appdata\local\programs\python\python37\lib\site-packages\sqlalchemy\engine\base.py", line 96, in __init__
    else engine.raw_connection()
  File "c:\users\fb\appdata\local\programs\python\python37\lib\site-packages\sqlalchemy\engine\base.py", line 3245, in raw_connection
    return self._wrap_pool_connect(self.pool.connect, _connection)
  File "c:\users\fb\appdata\local\programs\python\python37\lib\site-packages\sqlalchemy\engine\base.py", line 3216, in _wrap_pool_connect
    e, dialect, self
  File "c:\users\fb\appdata\local\programs\python\python37\lib\site-packages\sqlalchemy\engine\base.py", line 2070, in _handle_dbapi_exception_noconnection
    sqlalchemy_exception, with_traceback=exc_info[2], from_=e
  File "c:\users\fb\appdata\local\programs\python\python37\lib\site-packages\sqlalchemy\util\compat.py", line 207, in raise_
    raise exception
  File "c:\users\fb\appdata\local\programs\python\python37\lib\site-packages\sqlalchemy\engine\base.py", line 3212, in _wrap_pool_connect
    return fn()
  File "c:\users\fb\appdata\local\programs\python\python37\lib\site-packages\sqlalchemy\pool\base.py", line 307, in connect
    return _ConnectionFairy._checkout(self)
  File "c:\users\fb\appdata\local\programs\python\python37\lib\site-packages\sqlalchemy\pool\base.py", line 767, in _checkout
    fairy = _ConnectionRecord.checkout(pool)
  File "c:\users\fb\appdata\local\programs\python\python37\lib\site-packages\sqlalchemy\pool\base.py", line 425, in checkout
    rec = pool._do_get()
  File "c:\users\fb\appdata\local\programs\python\python37\lib\site-packages\sqlalchemy\pool\impl.py", line 146, in _do_get
    self._dec_overflow()
  File "c:\users\fb\appdata\local\programs\python\python37\lib\site-packages\sqlalchemy\util\langhelpers.py", line 72, in __exit__
    with_traceback=exc_tb,
  File "c:\users\fb\appdata\local\programs\python\python37\lib\site-packages\sqlalchemy\util\compat.py", line 207, in raise_
    raise exception
  File "c:\users\fb\appdata\local\programs\python\python37\lib\site-packages\sqlalchemy\pool\impl.py", line 143, in _do_get
    return self._create_connection()
  File "c:\users\fb\appdata\local\programs\python\python37\lib\site-packages\sqlalchemy\pool\base.py", line 253, in _create_connection
    return _ConnectionRecord(self)
  File "c:\users\fb\appdata\local\programs\python\python37\lib\site-packages\sqlalchemy\pool\base.py", line 368, in __init__
    self.__connect()
  File "c:\users\fb\appdata\local\programs\python\python37\lib\site-packages\sqlalchemy\pool\base.py", line 611, in __connect
    pool.logger.debug("Error on connect(): %s", e)
  File "c:\users\fb\appdata\local\programs\python\python37\lib\site-packages\sqlalchemy\util\langhelpers.py", line 72, in __exit__
    with_traceback=exc_tb,
  File "c:\users\fb\appdata\local\programs\python\python37\lib\site-packages\sqlalchemy\util\compat.py", line 207, in raise_
    raise exception
  File "c:\users\fb\appdata\local\programs\python\python37\lib\site-packages\sqlalchemy\pool\base.py", line 605, in __connect
    connection = pool._invoke_creator(self)
  File "c:\users\fb\appdata\local\programs\python\python37\lib\site-packages\sqlalchemy\engine\create.py", line 578, in connect
    return dialect.connect(*cargs, **cparams)
  File "c:\users\fb\appdata\local\programs\python\python37\lib\site-packages\sqlalchemy\engine\default.py", line 584, in connect
    return self.dbapi.connect(*cargs, **cparams)
  File "c:\users\fb\appdata\local\programs\python\python37\lib\site-packages\MySQLdb\__init__.py", line 130, in Connect
    return Connection(*args, **kwargs)
  File "c:\users\fb\appdata\local\programs\python\python37\lib\site-packages\MySQLdb\connections.py", line 185, in __init__
    super().__init__(*args, **kwargs2)
sqlalchemy.exc.OperationalError: (MySQLdb._exceptions.OperationalError) (2002, "Can't connect to MySQL server on 'localhost' (10061)")
(Background on this error at: https://sqlalche.me/e/14/e3q8)
