2021-08-15 16:26:11,148 ERROR: Exception on /api/users [GET] [in c:\users\fb\appdata\local\programs\python\python37\lib\site-packages\flask\app.py:1455]
Traceback (most recent call last):
  File "c:\users\fb\appdata\local\programs\python\python37\lib\site-packages\flask\app.py", line 2070, in wsgi_app
    response = self.full_dispatch_request()
  File "c:\users\fb\appdata\local\programs\python\python37\lib\site-packages\flask\app.py", line 1515, in full_dispatch_request
    rv = self.handle_user_exception(e)
  File "c:\users\fb\appdata\local\programs\python\python37\lib\site-packages\flask\app.py", line 1513, in full_dispatch_request
    rv = self.dispatch_request()
  File "c:\users\fb\appdata\local\programs\python\python37\lib\site-packages\flask\app.py", line 1499, in dispatch_request
    return self.ensure_sync(self.view_functions[rule.endpoint])(**req.view_args)
  File "c:\users\fb\appdata\local\programs\python\python37\lib\site-packages\flask_httpauth.py", line 161, in decorated
    user = self.authenticate(auth, password)
  File "c:\users\fb\appdata\local\programs\python\python37\lib\site-packages\flask_httpauth.py", line 366, in authenticate
    return self.verify_token_callback(token)
  File "C:\xampp\htdocs\onely\app\api\auth.py", line 27, in verify_token
    g.current_user = User.check_token(token) if token else None
  File "C:\xampp\htdocs\onely\app\models.py", line 214, in check_token
    if user is None or user.token_expiration < datetime.utcnow():
TypeError: '<' not supported between instances of 'NoneType' and 'datetime.datetime'
2021-08-15 16:27:07,988 ERROR: Exception on /api/users [GET] [in c:\users\fb\appdata\local\programs\python\python37\lib\site-packages\flask\app.py:1455]
Traceback (most recent call last):
  File "c:\users\fb\appdata\local\programs\python\python37\lib\site-packages\flask\app.py", line 2070, in wsgi_app
    response = self.full_dispatch_request()
  File "c:\users\fb\appdata\local\programs\python\python37\lib\site-packages\flask\app.py", line 1515, in full_dispatch_request
    rv = self.handle_user_exception(e)
  File "c:\users\fb\appdata\local\programs\python\python37\lib\site-packages\flask\app.py", line 1513, in full_dispatch_request
    rv = self.dispatch_request()
  File "c:\users\fb\appdata\local\programs\python\python37\lib\site-packages\flask\app.py", line 1499, in dispatch_request
    return self.ensure_sync(self.view_functions[rule.endpoint])(**req.view_args)
  File "c:\users\fb\appdata\local\programs\python\python37\lib\site-packages\flask_httpauth.py", line 161, in decorated
    user = self.authenticate(auth, password)
  File "c:\users\fb\appdata\local\programs\python\python37\lib\site-packages\flask_httpauth.py", line 366, in authenticate
    return self.verify_token_callback(token)
  File "C:\xampp\htdocs\onely\app\api\auth.py", line 27, in verify_token
    g.current_user = User.check_token(token) if token else None
  File "C:\xampp\htdocs\onely\app\models.py", line 214, in check_token
    if user is None or user.token_expiration < datetime.utcnow():
TypeError: '<' not supported between instances of 'NoneType' and 'datetime.datetime'
