2021-08-09 12:30:32,247 ERROR: Exception on /api/users [POST] [in c:\users\fb\appdata\local\programs\python\python37\lib\site-packages\flask\app.py:1455]
Traceback (most recent call last):
  File "c:\users\fb\appdata\local\programs\python\python37\lib\site-packages\flask\app.py", line 2070, in wsgi_app
    response = self.full_dispatch_request()
  File "c:\users\fb\appdata\local\programs\python\python37\lib\site-packages\flask\app.py", line 1515, in full_dispatch_request
    rv = self.handle_user_exception(e)
  File "c:\users\fb\appdata\local\programs\python\python37\lib\site-packages\flask\app.py", line 1513, in full_dispatch_request
    rv = self.dispatch_request()
  File "c:\users\fb\appdata\local\programs\python\python37\lib\site-packages\flask\app.py", line 1499, in dispatch_request
    return self.ensure_sync(self.view_functions[rule.endpoint])(**req.view_args)
  File "C:\xampp\htdocs\onely\app\api\users.py", line 164, in create_user
    response = jsonify(user.to_dict())
  File "C:\xampp\htdocs\onely\app\models.py", line 139, in to_dict
    'last_seen': int(float(self.last_seen.strftime('%s.%f'))*1000),
ValueError: Invalid format string
2021-08-09 12:31:34,321 ERROR: Exception on /api/users [POST] [in c:\users\fb\appdata\local\programs\python\python37\lib\site-packages\flask\app.py:1455]
Traceback (most recent call last):
  File "c:\users\fb\appdata\local\programs\python\python37\lib\site-packages\flask\app.py", line 2070, in wsgi_app
    response = self.full_dispatch_request()
  File "c:\users\fb\appdata\local\programs\python\python37\lib\site-packages\flask\app.py", line 1515, in full_dispatch_request
    rv = self.handle_user_exception(e)
  File "c:\users\fb\appdata\local\programs\python\python37\lib\site-packages\flask\app.py", line 1513, in full_dispatch_request
    rv = self.dispatch_request()
  File "c:\users\fb\appdata\local\programs\python\python37\lib\site-packages\flask\app.py", line 1499, in dispatch_request
    return self.ensure_sync(self.view_functions[rule.endpoint])(**req.view_args)
  File "C:\xampp\htdocs\onely\app\api\users.py", line 164, in create_user
    response = jsonify(user.to_dict())
  File "C:\xampp\htdocs\onely\app\models.py", line 139, in to_dict
    'last_seen': int(float(self.last_seen.strftime('%s.%f'))*1000),
ValueError: Invalid format string
2021-08-09 12:33:54,205 ERROR: Exception on /api/users [POST] [in c:\users\fb\appdata\local\programs\python\python37\lib\site-packages\flask\app.py:1455]
Traceback (most recent call last):
  File "c:\users\fb\appdata\local\programs\python\python37\lib\site-packages\flask\app.py", line 2070, in wsgi_app
    response = self.full_dispatch_request()
  File "c:\users\fb\appdata\local\programs\python\python37\lib\site-packages\flask\app.py", line 1515, in full_dispatch_request
    rv = self.handle_user_exception(e)
  File "c:\users\fb\appdata\local\programs\python\python37\lib\site-packages\flask\app.py", line 1513, in full_dispatch_request
    rv = self.dispatch_request()
  File "c:\users\fb\appdata\local\programs\python\python37\lib\site-packages\flask\app.py", line 1499, in dispatch_request
    return self.ensure_sync(self.view_functions[rule.endpoint])(**req.view_args)
  File "C:\xampp\htdocs\onely\app\api\users.py", line 164, in create_user
    response = jsonify(user.to_dict())
  File "C:\xampp\htdocs\onely\app\models.py", line 139, in to_dict
    'last_seen': 1000,
ValueError: Invalid format string
2021-08-09 12:38:42,452 INFO: Strefi startup [in C:\xampp\htdocs\onely\app\__init__.py:90]
2021-08-09 12:38:48,060 ERROR: Exception on /api/users [POST] [in c:\users\fb\appdata\local\programs\python\python37\lib\site-packages\flask\app.py:1455]
Traceback (most recent call last):
  File "c:\users\fb\appdata\local\programs\python\python37\lib\site-packages\flask\app.py", line 2070, in wsgi_app
    response = self.full_dispatch_request()
  File "c:\users\fb\appdata\local\programs\python\python37\lib\site-packages\flask\app.py", line 1515, in full_dispatch_request
    rv = self.handle_user_exception(e)
  File "c:\users\fb\appdata\local\programs\python\python37\lib\site-packages\flask\app.py", line 1513, in full_dispatch_request
    rv = self.dispatch_request()
  File "c:\users\fb\appdata\local\programs\python\python37\lib\site-packages\flask\app.py", line 1499, in dispatch_request
    return self.ensure_sync(self.view_functions[rule.endpoint])(**req.view_args)
  File "C:\xampp\htdocs\onely\app\api\users.py", line 152, in create_user
    return int(float(self.last_seen.strftime('%s.%f'))*1000)
NameError: name 'self' is not defined
2021-08-09 12:39:18,376 INFO: Strefi startup [in C:\xampp\htdocs\onely\app\__init__.py:90]
2021-08-09 12:39:19,324 ERROR: Exception on /api/users [POST] [in c:\users\fb\appdata\local\programs\python\python37\lib\site-packages\flask\app.py:1455]
Traceback (most recent call last):
  File "c:\users\fb\appdata\local\programs\python\python37\lib\site-packages\flask\app.py", line 2070, in wsgi_app
    response = self.full_dispatch_request()
  File "c:\users\fb\appdata\local\programs\python\python37\lib\site-packages\flask\app.py", line 1516, in full_dispatch_request
    return self.finalize_request(rv)
  File "c:\users\fb\appdata\local\programs\python\python37\lib\site-packages\flask\app.py", line 1535, in finalize_request
    response = self.make_response(rv)
  File "c:\users\fb\appdata\local\programs\python\python37\lib\site-packages\flask\app.py", line 1728, in make_response
    "The view function did not return a valid"
TypeError: The view function did not return a valid response. The return type must be a string, dict, tuple, Response instance, or WSGI callable, but it was a int.
2021-08-09 12:39:36,750 INFO: Strefi startup [in C:\xampp\htdocs\onely\app\__init__.py:90]
2021-08-09 12:41:08,044 INFO: Strefi startup [in C:\xampp\htdocs\onely\app\__init__.py:90]
2021-08-09 12:42:31,534 INFO: Strefi startup [in C:\xampp\htdocs\onely\app\__init__.py:90]
2021-08-09 12:42:33,399 ERROR: Exception on /api/users [POST] [in c:\users\fb\appdata\local\programs\python\python37\lib\site-packages\flask\app.py:1455]
Traceback (most recent call last):
  File "c:\users\fb\appdata\local\programs\python\python37\lib\site-packages\flask\app.py", line 2070, in wsgi_app
    response = self.full_dispatch_request()
  File "c:\users\fb\appdata\local\programs\python\python37\lib\site-packages\flask\app.py", line 1515, in full_dispatch_request
    rv = self.handle_user_exception(e)
  File "c:\users\fb\appdata\local\programs\python\python37\lib\site-packages\flask\app.py", line 1513, in full_dispatch_request
    rv = self.dispatch_request()
  File "c:\users\fb\appdata\local\programs\python\python37\lib\site-packages\flask\app.py", line 1499, in dispatch_request
    return self.ensure_sync(self.view_functions[rule.endpoint])(**req.view_args)
  File "C:\xampp\htdocs\onely\app\api\users.py", line 152, in create_user
    last_seen = db.Column(db.DateTime, default=datetime.utcnow)
AttributeError: module 'datetime' has no attribute 'utcnow'
2021-08-09 12:44:58,086 INFO: Strefi startup [in C:\xampp\htdocs\onely\app\__init__.py:90]
2021-08-09 13:01:03,715 INFO: Strefi startup [in C:\xampp\htdocs\onely\app\__init__.py:90]
