2021-08-15 16:26:11,148 ERROR: Exception on /api/users [GET] [in c:\users\fb\appdata\local\programs\python\python37\lib\site-packages\flask\app.py:1455]
Traceback (most recent call last):
  File "c:\users\fb\appdata\local\programs\python\python37\lib\site-packages\flask\app.py", line 2070, in wsgi_app
    response = self.full_dispatch_request()
  File "c:\users\fb\appdata\local\programs\python\python37\lib\site-packages\flask\app.py", line 1515, in full_dispatch_request
    rv = self.handle_user_exception(e)
  File "c:\users\fb\appdata\local\programs\python\python37\lib\site-packages\flask\app.py", line 1513, in full_dispatch_request
    rv = self.dispatch_request()
  File "c:\users\fb\appdata\local\programs\python\python37\lib\site-packages\flask\app.py", line 1499, in dispatch_request
    return self.ensure_sync(self.view_functions[rule.endpoint])(**req.view_args)
  File "c:\users\fb\appdata\local\programs\python\python37\lib\site-packages\flask_httpauth.py", line 161, in decorated
    user = self.authenticate(auth, password)
  File "c:\users\fb\appdata\local\programs\python\python37\lib\site-packages\flask_httpauth.py", line 366, in authenticate
    return self.verify_token_callback(token)
  File "C:\xampp\htdocs\onely\app\api\auth.py", line 27, in verify_token
    g.current_user = User.check_token(token) if token else None
  File "C:\xampp\htdocs\onely\app\models.py", line 214, in check_token
    if user is None or user.token_expiration < datetime.utcnow():
TypeError: '<' not supported between instances of 'NoneType' and 'datetime.datetime'
2021-08-15 16:27:07,988 ERROR: Exception on /api/users [GET] [in c:\users\fb\appdata\local\programs\python\python37\lib\site-packages\flask\app.py:1455]
Traceback (most recent call last):
  File "c:\users\fb\appdata\local\programs\python\python37\lib\site-packages\flask\app.py", line 2070, in wsgi_app
    response = self.full_dispatch_request()
  File "c:\users\fb\appdata\local\programs\python\python37\lib\site-packages\flask\app.py", line 1515, in full_dispatch_request
    rv = self.handle_user_exception(e)
  File "c:\users\fb\appdata\local\programs\python\python37\lib\site-packages\flask\app.py", line 1513, in full_dispatch_request
    rv = self.dispatch_request()
  File "c:\users\fb\appdata\local\programs\python\python37\lib\site-packages\flask\app.py", line 1499, in dispatch_request
    return self.ensure_sync(self.view_functions[rule.endpoint])(**req.view_args)
  File "c:\users\fb\appdata\local\programs\python\python37\lib\site-packages\flask_httpauth.py", line 161, in decorated
    user = self.authenticate(auth, password)
  File "c:\users\fb\appdata\local\programs\python\python37\lib\site-packages\flask_httpauth.py", line 366, in authenticate
    return self.verify_token_callback(token)
  File "C:\xampp\htdocs\onely\app\api\auth.py", line 27, in verify_token
    g.current_user = User.check_token(token) if token else None
  File "C:\xampp\htdocs\onely\app\models.py", line 214, in check_token
    if user is None or user.token_expiration < datetime.utcnow():
TypeError: '<' not supported between instances of 'NoneType' and 'datetime.datetime'
2021-08-16 12:03:58,190 INFO: Strefi startup [in C:\xampp\htdocs\onely\app\__init__.py:90]
2021-08-16 16:00:47,872 INFO: Strefi startup [in C:\xampp\htdocs\onely\app\__init__.py:90]
2021-08-17 11:48:53,234 ERROR: Exception on /api/discover [POST] [in c:\users\fb\appdata\local\programs\python\python37\lib\site-packages\flask\app.py:1455]
Traceback (most recent call last):
  File "c:\users\fb\appdata\local\programs\python\python37\lib\site-packages\flask\app.py", line 2070, in wsgi_app
    response = self.full_dispatch_request()
  File "c:\users\fb\appdata\local\programs\python\python37\lib\site-packages\flask\app.py", line 1515, in full_dispatch_request
    rv = self.handle_user_exception(e)
  File "c:\users\fb\appdata\local\programs\python\python37\lib\site-packages\flask\app.py", line 1513, in full_dispatch_request
    rv = self.dispatch_request()
  File "c:\users\fb\appdata\local\programs\python\python37\lib\site-packages\flask\app.py", line 1499, in dispatch_request
    return self.ensure_sync(self.view_functions[rule.endpoint])(**req.view_args)
  File "c:\users\fb\appdata\local\programs\python\python37\lib\site-packages\flask_httpauth.py", line 176, in decorated
    return f(*args, **kwargs)
  File "C:\xampp\htdocs\onely\app\api\songs.py", line 44, in discover
    user_gender = g.current_user.gender[0].lower()
TypeError: 'NoneType' object is not subscriptable
2021-08-17 13:25:55,394 ERROR: Exception on /api/discover [POST] [in c:\users\fb\appdata\local\programs\python\python37\lib\site-packages\flask\app.py:1455]
Traceback (most recent call last):
  File "c:\users\fb\appdata\local\programs\python\python37\lib\site-packages\flask\app.py", line 2070, in wsgi_app
    response = self.full_dispatch_request()
  File "c:\users\fb\appdata\local\programs\python\python37\lib\site-packages\flask\app.py", line 1515, in full_dispatch_request
    rv = self.handle_user_exception(e)
  File "c:\users\fb\appdata\local\programs\python\python37\lib\site-packages\flask\app.py", line 1513, in full_dispatch_request
    rv = self.dispatch_request()
  File "c:\users\fb\appdata\local\programs\python\python37\lib\site-packages\flask\app.py", line 1499, in dispatch_request
    return self.ensure_sync(self.view_functions[rule.endpoint])(**req.view_args)
  File "c:\users\fb\appdata\local\programs\python\python37\lib\site-packages\flask_httpauth.py", line 176, in decorated
    return f(*args, **kwargs)
  File "C:\xampp\htdocs\onely\app\api\songs.py", line 44, in discover
    user_gender = g.current_user.gender[0].lower()
TypeError: 'NoneType' object is not subscriptable
2021-08-17 13:25:59,111 ERROR: Exception on /api/discover [POST] [in c:\users\fb\appdata\local\programs\python\python37\lib\site-packages\flask\app.py:1455]
Traceback (most recent call last):
  File "c:\users\fb\appdata\local\programs\python\python37\lib\site-packages\flask\app.py", line 2070, in wsgi_app
    response = self.full_dispatch_request()
  File "c:\users\fb\appdata\local\programs\python\python37\lib\site-packages\flask\app.py", line 1515, in full_dispatch_request
    rv = self.handle_user_exception(e)
  File "c:\users\fb\appdata\local\programs\python\python37\lib\site-packages\flask\app.py", line 1513, in full_dispatch_request
    rv = self.dispatch_request()
  File "c:\users\fb\appdata\local\programs\python\python37\lib\site-packages\flask\app.py", line 1499, in dispatch_request
    return self.ensure_sync(self.view_functions[rule.endpoint])(**req.view_args)
  File "c:\users\fb\appdata\local\programs\python\python37\lib\site-packages\flask_httpauth.py", line 176, in decorated
    return f(*args, **kwargs)
  File "C:\xampp\htdocs\onely\app\api\songs.py", line 44, in discover
    user_gender = g.current_user.gender[0].lower()
TypeError: 'NoneType' object is not subscriptable
2021-08-21 09:35:37,570 ERROR: Exception on /api/discover [POST] [in c:\users\fb\appdata\local\programs\python\python37\lib\site-packages\flask\app.py:1455]
Traceback (most recent call last):
  File "c:\users\fb\appdata\local\programs\python\python37\lib\site-packages\flask\app.py", line 2070, in wsgi_app
    response = self.full_dispatch_request()
  File "c:\users\fb\appdata\local\programs\python\python37\lib\site-packages\flask\app.py", line 1515, in full_dispatch_request
    rv = self.handle_user_exception(e)
  File "c:\users\fb\appdata\local\programs\python\python37\lib\site-packages\flask\app.py", line 1513, in full_dispatch_request
    rv = self.dispatch_request()
  File "c:\users\fb\appdata\local\programs\python\python37\lib\site-packages\flask\app.py", line 1499, in dispatch_request
    return self.ensure_sync(self.view_functions[rule.endpoint])(**req.view_args)
  File "c:\users\fb\appdata\local\programs\python\python37\lib\site-packages\flask_httpauth.py", line 176, in decorated
    return f(*args, **kwargs)
  File "C:\xampp\htdocs\onely\app\api\songs.py", line 44, in discover
    user_gender = g.current_user.gender[0].lower()
TypeError: 'NoneType' object is not subscriptable
2021-08-21 09:36:27,202 INFO: Strefi startup [in C:\xampp\htdocs\onely\app\__init__.py:90]
2021-08-21 09:36:30,467 ERROR: Exception on /api/discover [POST] [in c:\users\fb\appdata\local\programs\python\python37\lib\site-packages\flask\app.py:1455]
Traceback (most recent call last):
  File "c:\users\fb\appdata\local\programs\python\python37\lib\site-packages\flask\app.py", line 2070, in wsgi_app
    response = self.full_dispatch_request()
  File "c:\users\fb\appdata\local\programs\python\python37\lib\site-packages\flask\app.py", line 1515, in full_dispatch_request
    rv = self.handle_user_exception(e)
  File "c:\users\fb\appdata\local\programs\python\python37\lib\site-packages\flask\app.py", line 1513, in full_dispatch_request
    rv = self.dispatch_request()
  File "c:\users\fb\appdata\local\programs\python\python37\lib\site-packages\flask\app.py", line 1499, in dispatch_request
    return self.ensure_sync(self.view_functions[rule.endpoint])(**req.view_args)
  File "c:\users\fb\appdata\local\programs\python\python37\lib\site-packages\flask_httpauth.py", line 176, in decorated
    return f(*args, **kwargs)
  File "C:\xampp\htdocs\onely\app\api\songs.py", line 44, in discover
    user_gender = g.current_user.gender[0].lower()
TypeError: 'NoneType' object is not subscriptable
2021-08-21 09:37:19,472 INFO: Strefi startup [in C:\xampp\htdocs\onely\app\__init__.py:90]
