2021-09-28 16:15:48,883 ERROR: Exception on /liverequests [GET] [in c:\users\fb\appdata\local\programs\python\python37\lib\site-packages\flask\app.py:1455]
Traceback (most recent call last):
  File "c:\users\fb\appdata\local\programs\python\python37\lib\site-packages\flask\app.py", line 2070, in wsgi_app
    response = self.full_dispatch_request()
  File "c:\users\fb\appdata\local\programs\python\python37\lib\site-packages\flask\app.py", line 1515, in full_dispatch_request
    rv = self.handle_user_exception(e)
  File "c:\users\fb\appdata\local\programs\python\python37\lib\site-packages\flask\app.py", line 1513, in full_dispatch_request
    rv = self.dispatch_request()
  File "c:\users\fb\appdata\local\programs\python\python37\lib\site-packages\flask\app.py", line 1499, in dispatch_request
    return self.ensure_sync(self.view_functions[rule.endpoint])(**req.view_args)
  File "C:\xampp\htdocs\onely\app\main\routes.py", line 35, in liverequests
    return jsonify(requests)
  File "c:\users\fb\appdata\local\programs\python\python37\lib\site-packages\flask\json\__init__.py", line 348, in jsonify
    f"{dumps(data, indent=indent, separators=separators)}\n",
  File "c:\users\fb\appdata\local\programs\python\python37\lib\site-packages\flask\json\__init__.py", line 129, in dumps
    rv = _json.dumps(obj, **kwargs)
  File "c:\users\fb\appdata\local\programs\python\python37\lib\json\__init__.py", line 238, in dumps
    **kw).encode(obj)
  File "c:\users\fb\appdata\local\programs\python\python37\lib\json\encoder.py", line 199, in encode
    chunks = self.iterencode(o, _one_shot=True)
  File "c:\users\fb\appdata\local\programs\python\python37\lib\json\encoder.py", line 257, in iterencode
    return _iterencode(o, 0)
  File "c:\users\fb\appdata\local\programs\python\python37\lib\site-packages\flask\json\__init__.py", line 56, in default
    return super().default(o)
  File "c:\users\fb\appdata\local\programs\python\python37\lib\json\encoder.py", line 179, in default
    raise TypeError(f'Object of type {o.__class__.__name__} '
TypeError: Object of type BaseQuery is not JSON serializable
2021-09-28 16:17:23,271 INFO: Strefi startup [in C:\xampp\htdocs\onely\app\__init__.py:90]
2021-09-28 16:41:20,639 INFO: Strefi startup [in C:\xampp\htdocs\onely\app\__init__.py:90]
2021-09-28 16:41:22,082 ERROR: Exception on /liverequests [GET] [in c:\users\fb\appdata\local\programs\python\python37\lib\site-packages\flask\app.py:1455]
Traceback (most recent call last):
  File "c:\users\fb\appdata\local\programs\python\python37\lib\site-packages\flask\app.py", line 2070, in wsgi_app
    response = self.full_dispatch_request()
  File "c:\users\fb\appdata\local\programs\python\python37\lib\site-packages\flask\app.py", line 1515, in full_dispatch_request
    rv = self.handle_user_exception(e)
  File "c:\users\fb\appdata\local\programs\python\python37\lib\site-packages\flask\app.py", line 1513, in full_dispatch_request
    rv = self.dispatch_request()
  File "c:\users\fb\appdata\local\programs\python\python37\lib\site-packages\flask\app.py", line 1499, in dispatch_request
    return self.ensure_sync(self.view_functions[rule.endpoint])(**req.view_args)
  File "C:\xampp\htdocs\onely\app\main\routes.py", line 35, in liverequests
    requests = db.engine.execute("SELECT user.username,user.id,user.email,user.name,user.avatar, live_requests.live_request  from user, live_requests where live_requests.user_id=user.id")
NameError: name 'db' is not defined
2021-09-28 16:41:56,873 INFO: Strefi startup [in C:\xampp\htdocs\onely\app\__init__.py:90]
2021-09-28 16:41:58,006 ERROR: Exception on /liverequests [GET] [in c:\users\fb\appdata\local\programs\python\python37\lib\site-packages\flask\app.py:1455]
Traceback (most recent call last):
  File "c:\users\fb\appdata\local\programs\python\python37\lib\site-packages\flask\app.py", line 2070, in wsgi_app
    response = self.full_dispatch_request()
  File "c:\users\fb\appdata\local\programs\python\python37\lib\site-packages\flask\app.py", line 1515, in full_dispatch_request
    rv = self.handle_user_exception(e)
  File "c:\users\fb\appdata\local\programs\python\python37\lib\site-packages\flask\app.py", line 1513, in full_dispatch_request
    rv = self.dispatch_request()
  File "c:\users\fb\appdata\local\programs\python\python37\lib\site-packages\flask\app.py", line 1499, in dispatch_request
    return self.ensure_sync(self.view_functions[rule.endpoint])(**req.view_args)
  File "C:\xampp\htdocs\onely\app\main\routes.py", line 44, in liverequests
    } for request in requests]
  File "C:\xampp\htdocs\onely\app\main\routes.py", line 44, in <listcomp>
    } for request in requests]
AttributeError: Could not locate column in row for column 'user_id'
2021-09-28 16:42:42,353 INFO: Strefi startup [in C:\xampp\htdocs\onely\app\__init__.py:90]
2021-09-28 16:46:32,518 INFO: Strefi startup [in C:\xampp\htdocs\onely\app\__init__.py:90]
2021-09-28 16:46:34,220 ERROR: Exception on /liverequests [GET] [in c:\users\fb\appdata\local\programs\python\python37\lib\site-packages\flask\app.py:1455]
Traceback (most recent call last):
  File "c:\users\fb\appdata\local\programs\python\python37\lib\site-packages\flask\app.py", line 2070, in wsgi_app
    response = self.full_dispatch_request()
  File "c:\users\fb\appdata\local\programs\python\python37\lib\site-packages\flask\app.py", line 1515, in full_dispatch_request
    rv = self.handle_user_exception(e)
  File "c:\users\fb\appdata\local\programs\python\python37\lib\site-packages\flask\app.py", line 1513, in full_dispatch_request
    rv = self.dispatch_request()
  File "c:\users\fb\appdata\local\programs\python\python37\lib\site-packages\flask\app.py", line 1499, in dispatch_request
    return self.ensure_sync(self.view_functions[rule.endpoint])(**req.view_args)
  File "C:\xampp\htdocs\onely\app\main\routes.py", line 49, in liverequests
    return render_template('liverequests.html', all_requests=all_requests)
  File "c:\users\fb\appdata\local\programs\python\python37\lib\site-packages\flask\templating.py", line 150, in render_template
    ctx.app,
  File "c:\users\fb\appdata\local\programs\python\python37\lib\site-packages\flask\templating.py", line 128, in _render
    rv = template.render(context)
  File "c:\users\fb\appdata\local\programs\python\python37\lib\site-packages\jinja2\environment.py", line 1304, in render
    self.environment.handle_exception()
  File "c:\users\fb\appdata\local\programs\python\python37\lib\site-packages\jinja2\environment.py", line 925, in handle_exception
    raise rewrite_traceback_stack(source=source)
  File "C:\xampp\htdocs\onely\app\templates\liverequests.html", line 42, in top-level template code
    <!--        <td>{{user.photo}}</td>-->
  File "c:\users\fb\appdata\local\programs\python\python37\lib\site-packages\jinja2\environment.py", line 474, in getattr
    return getattr(obj, attribute)
jinja2.exceptions.UndefinedError: 'user' is undefined
2021-09-28 16:47:29,442 INFO: Strefi startup [in C:\xampp\htdocs\onely\app\__init__.py:90]
2021-09-28 16:47:30,648 ERROR: Exception on /liverequests [GET] [in c:\users\fb\appdata\local\programs\python\python37\lib\site-packages\flask\app.py:1455]
Traceback (most recent call last):
  File "c:\users\fb\appdata\local\programs\python\python37\lib\site-packages\flask\app.py", line 2070, in wsgi_app
    response = self.full_dispatch_request()
  File "c:\users\fb\appdata\local\programs\python\python37\lib\site-packages\flask\app.py", line 1515, in full_dispatch_request
    rv = self.handle_user_exception(e)
  File "c:\users\fb\appdata\local\programs\python\python37\lib\site-packages\flask\app.py", line 1513, in full_dispatch_request
    rv = self.dispatch_request()
  File "c:\users\fb\appdata\local\programs\python\python37\lib\site-packages\flask\app.py", line 1499, in dispatch_request
    return self.ensure_sync(self.view_functions[rule.endpoint])(**req.view_args)
  File "C:\xampp\htdocs\onely\app\main\routes.py", line 49, in liverequests
    return render_template('liverequests.html', all_requests=all_requests)
  File "c:\users\fb\appdata\local\programs\python\python37\lib\site-packages\flask\templating.py", line 150, in render_template
    ctx.app,
  File "c:\users\fb\appdata\local\programs\python\python37\lib\site-packages\flask\templating.py", line 128, in _render
    rv = template.render(context)
  File "c:\users\fb\appdata\local\programs\python\python37\lib\site-packages\jinja2\environment.py", line 1304, in render
    self.environment.handle_exception()
  File "c:\users\fb\appdata\local\programs\python\python37\lib\site-packages\jinja2\environment.py", line 925, in handle_exception
    raise rewrite_traceback_stack(source=source)
  File "C:\xampp\htdocs\onely\app\templates\liverequests.html", line 42, in top-level template code
    <!--        <td>{{user.photo}}</td>-->
  File "c:\users\fb\appdata\local\programs\python\python37\lib\site-packages\jinja2\environment.py", line 474, in getattr
    return getattr(obj, attribute)
jinja2.exceptions.UndefinedError: 'user' is undefined
2021-09-28 16:54:09,447 INFO: Strefi startup [in C:\xampp\htdocs\onely\app\__init__.py:90]
