2021-08-03 15:49:25,846 ERROR: Exception on /api/tokens [POST] [in c:\users\fb\appdata\local\programs\python\python37\lib\site-packages\flask\app.py:1455]
Traceback (most recent call last):
  File "c:\users\fb\appdata\local\programs\python\python37\lib\site-packages\sqlalchemy\engine\base.py", line 1772, in _execute_context
    cursor, statement, parameters, context
  File "c:\users\fb\appdata\local\programs\python\python37\lib\site-packages\sqlalchemy\engine\default.py", line 717, in do_execute
    cursor.execute(statement, parameters)
  File "c:\users\fb\appdata\local\programs\python\python37\lib\site-packages\MySQLdb\cursors.py", line 206, in execute
    res = self._query(query)
  File "c:\users\fb\appdata\local\programs\python\python37\lib\site-packages\MySQLdb\cursors.py", line 319, in _query
    db.query(q)
  File "c:\users\fb\appdata\local\programs\python\python37\lib\site-packages\MySQLdb\connections.py", line 259, in query
    _mysql.connection.query(self, query)
MySQLdb._exceptions.ProgrammingError: (1146, "Table 'onely.user' doesn't exist")

The above exception was the direct cause of the following exception:

Traceback (most recent call last):
  File "c:\users\fb\appdata\local\programs\python\python37\lib\site-packages\flask\app.py", line 2070, in wsgi_app
    response = self.full_dispatch_request()
  File "c:\users\fb\appdata\local\programs\python\python37\lib\site-packages\flask\app.py", line 1515, in full_dispatch_request
    rv = self.handle_user_exception(e)
  File "c:\users\fb\appdata\local\programs\python\python37\lib\site-packages\flask\app.py", line 1513, in full_dispatch_request
    rv = self.dispatch_request()
  File "c:\users\fb\appdata\local\programs\python\python37\lib\site-packages\flask\app.py", line 1499, in dispatch_request
    return self.ensure_sync(self.view_functions[rule.endpoint])(**req.view_args)
  File "c:\users\fb\appdata\local\programs\python\python37\lib\site-packages\flask_httpauth.py", line 161, in decorated
    user = self.authenticate(auth, password)
  File "c:\users\fb\appdata\local\programs\python\python37\lib\site-packages\flask_httpauth.py", line 238, in authenticate
    return self.verify_password_callback(username, client_password)
  File "C:\xampp\htdocs\onely\app\api\auth.py", line 13, in verify_password
    user = User.query.filter_by(username=username).first()
  File "c:\users\fb\appdata\local\programs\python\python37\lib\site-packages\sqlalchemy\orm\query.py", line 2763, in first
    return self.limit(1)._iter().first()
  File "c:\users\fb\appdata\local\programs\python\python37\lib\site-packages\sqlalchemy\orm\query.py", line 2850, in _iter
    execution_options={"_sa_orm_load_options": self.load_options},
  File "c:\users\fb\appdata\local\programs\python\python37\lib\site-packages\sqlalchemy\orm\session.py", line 1689, in execute
    result = conn._execute_20(statement, params or {}, execution_options)
  File "c:\users\fb\appdata\local\programs\python\python37\lib\site-packages\sqlalchemy\engine\base.py", line 1583, in _execute_20
    return meth(self, args_10style, kwargs_10style, execution_options)
  File "c:\users\fb\appdata\local\programs\python\python37\lib\site-packages\sqlalchemy\sql\elements.py", line 324, in _execute_on_connection
    self, multiparams, params, execution_options
  File "c:\users\fb\appdata\local\programs\python\python37\lib\site-packages\sqlalchemy\engine\base.py", line 1462, in _execute_clauseelement
    cache_hit=cache_hit,
  File "c:\users\fb\appdata\local\programs\python\python37\lib\site-packages\sqlalchemy\engine\base.py", line 1815, in _execute_context
    e, statement, parameters, cursor, context
  File "c:\users\fb\appdata\local\programs\python\python37\lib\site-packages\sqlalchemy\engine\base.py", line 1996, in _handle_dbapi_exception
    sqlalchemy_exception, with_traceback=exc_info[2], from_=e
  File "c:\users\fb\appdata\local\programs\python\python37\lib\site-packages\sqlalchemy\util\compat.py", line 207, in raise_
    raise exception
  File "c:\users\fb\appdata\local\programs\python\python37\lib\site-packages\sqlalchemy\engine\base.py", line 1772, in _execute_context
    cursor, statement, parameters, context
  File "c:\users\fb\appdata\local\programs\python\python37\lib\site-packages\sqlalchemy\engine\default.py", line 717, in do_execute
    cursor.execute(statement, parameters)
  File "c:\users\fb\appdata\local\programs\python\python37\lib\site-packages\MySQLdb\cursors.py", line 206, in execute
    res = self._query(query)
  File "c:\users\fb\appdata\local\programs\python\python37\lib\site-packages\MySQLdb\cursors.py", line 319, in _query
    db.query(q)
  File "c:\users\fb\appdata\local\programs\python\python37\lib\site-packages\MySQLdb\connections.py", line 259, in query
    _mysql.connection.query(self, query)
sqlalchemy.exc.ProgrammingError: (MySQLdb._exceptions.ProgrammingError) (1146, "Table 'onely.user' doesn't exist")
[SQL: SELECT user.id AS user_id, user.username AS user_username, user.name AS user_name, user.email AS user_email, user.country AS user_country, user.phone_number AS user_phone_number, user.birthday AS user_birthday, user.gender AS user_gender, user.looking_for AS user_looking_for, user.genres AS user_genres, user.artists AS user_artists, user.questions AS user_questions, user.anthem AS user_anthem, user.bio AS user_bio, user.location AS user_location, user.discover_location AS user_discover_location, user.height AS user_height, user.hometown AS user_hometown, user.ethnicity AS user_ethnicity, user.job AS user_job, user.education AS user_education, user.religion AS user_religion, user.company AS user_company, user.instagram AS user_instagram, user.password_hash AS user_password_hash, user.avatar AS user_avatar, user.photo1 AS user_photo1, user.photo2 AS user_photo2, user.photo3 AS user_photo3, user.photo4 AS user_photo4, user.photo5 AS user_photo5, user.photo6 AS user_photo6, user.`favoriteSongs` AS `user_favoriteSongs`, user.`favoriteAlbums` AS `user_favoriteAlbums`, user.`favoritePlaylists` AS `user_favoritePlaylists`, user.`favoriteArtists` AS `user_favoriteArtists`, user.`favoriteGenres` AS `user_favoriteGenres`, user.verification_code AS user_verification_code, user.verified AS user_verified, user.last_seen AS user_last_seen, user.creation_date AS user_creation_date, user.token AS user_token, user.token_expiration AS user_token_expiration 
FROM user 
WHERE user.username = %s 
 LIMIT %s]
[parameters: ('aliahmed', 1)]
(Background on this error at: https://sqlalche.me/e/14/f405)
2021-08-09 12:04:03,188 INFO: Strefi startup [in C:\xampp\htdocs\onely\app\__init__.py:90]
2021-08-09 12:09:59,154 INFO: Strefi startup [in C:\xampp\htdocs\onely\app\__init__.py:90]
2021-08-09 12:16:22,971 ERROR: Exception on /api/users [POST] [in c:\users\fb\appdata\local\programs\python\python37\lib\site-packages\flask\app.py:1455]
Traceback (most recent call last):
  File "c:\users\fb\appdata\local\programs\python\python37\lib\site-packages\flask\app.py", line 2070, in wsgi_app
    response = self.full_dispatch_request()
  File "c:\users\fb\appdata\local\programs\python\python37\lib\site-packages\flask\app.py", line 1515, in full_dispatch_request
    rv = self.handle_user_exception(e)
  File "c:\users\fb\appdata\local\programs\python\python37\lib\site-packages\flask\app.py", line 1513, in full_dispatch_request
    rv = self.dispatch_request()
  File "c:\users\fb\appdata\local\programs\python\python37\lib\site-packages\flask\app.py", line 1499, in dispatch_request
    return self.ensure_sync(self.view_functions[rule.endpoint])(**req.view_args)
  File "C:\xampp\htdocs\onely\app\api\users.py", line 164, in create_user
    response = jsonify(user.to_dict())
  File "C:\xampp\htdocs\onely\app\models.py", line 139, in to_dict
    'last_seen': int(float(self.last_seen.strftime('%s.%f'))*1000),
ValueError: Invalid format string
2021-08-09 12:29:53,245 ERROR: Exception on /api/users [POST] [in c:\users\fb\appdata\local\programs\python\python37\lib\site-packages\flask\app.py:1455]
Traceback (most recent call last):
  File "c:\users\fb\appdata\local\programs\python\python37\lib\site-packages\flask\app.py", line 2070, in wsgi_app
    response = self.full_dispatch_request()
  File "c:\users\fb\appdata\local\programs\python\python37\lib\site-packages\flask\app.py", line 1515, in full_dispatch_request
    rv = self.handle_user_exception(e)
  File "c:\users\fb\appdata\local\programs\python\python37\lib\site-packages\flask\app.py", line 1513, in full_dispatch_request
    rv = self.dispatch_request()
  File "c:\users\fb\appdata\local\programs\python\python37\lib\site-packages\flask\app.py", line 1499, in dispatch_request
    return self.ensure_sync(self.view_functions[rule.endpoint])(**req.view_args)
  File "C:\xampp\htdocs\onely\app\api\users.py", line 164, in create_user
    response = jsonify(user.to_dict())
  File "C:\xampp\htdocs\onely\app\models.py", line 139, in to_dict
    'last_seen': int(float(self.last_seen.strftime('%s.%f'))*1000),
ValueError: Invalid format string
