2021-08-03 15:46:54,654 ERROR: Exception on /api/tokens [POST] [in c:\users\fb\appdata\local\programs\python\python37\lib\site-packages\flask\app.py:1455]
Traceback (most recent call last):
  File "c:\users\fb\appdata\local\programs\python\python37\lib\site-packages\sqlalchemy\util\_collections.py", line 1008, in __call__
    return self.registry[key]
KeyError: <greenlet.greenlet object at 0x000001BBCF171888 (otid=0x000001BBCF2743F0) current active started main>

During handling of the above exception, another exception occurred:

Traceback (most recent call last):
  File "c:\users\fb\appdata\local\programs\python\python37\lib\site-packages\flask\app.py", line 2070, in wsgi_app
    response = self.full_dispatch_request()
  File "c:\users\fb\appdata\local\programs\python\python37\lib\site-packages\flask\app.py", line 1515, in full_dispatch_request
    rv = self.handle_user_exception(e)
  File "c:\users\fb\appdata\local\programs\python\python37\lib\site-packages\flask\app.py", line 1513, in full_dispatch_request
    rv = self.dispatch_request()
  File "c:\users\fb\appdata\local\programs\python\python37\lib\site-packages\flask\app.py", line 1499, in dispatch_request
    return self.ensure_sync(self.view_functions[rule.endpoint])(**req.view_args)
  File "c:\users\fb\appdata\local\programs\python\python37\lib\site-packages\flask_httpauth.py", line 161, in decorated
    user = self.authenticate(auth, password)
  File "c:\users\fb\appdata\local\programs\python\python37\lib\site-packages\flask_httpauth.py", line 238, in authenticate
    return self.verify_password_callback(username, client_password)
  File "C:\xampp\htdocs\onely\app\api\auth.py", line 13, in verify_password
    user = User.query.filter_by(username=username).first()
  File "c:\users\fb\appdata\local\programs\python\python37\lib\site-packages\flask_sqlalchemy\__init__.py", line 552, in __get__
    return type.query_class(mapper, session=self.sa.session())
  File "c:\users\fb\appdata\local\programs\python\python37\lib\site-packages\sqlalchemy\orm\scoping.py", line 47, in __call__
    return self.registry()
  File "c:\users\fb\appdata\local\programs\python\python37\lib\site-packages\sqlalchemy\util\_collections.py", line 1010, in __call__
    return self.registry.setdefault(key, self.createfunc())
  File "c:\users\fb\appdata\local\programs\python\python37\lib\site-packages\sqlalchemy\orm\session.py", line 4101, in __call__
    return self.class_(**local_kw)
  File "c:\users\fb\appdata\local\programs\python\python37\lib\site-packages\flask_sqlalchemy\__init__.py", line 176, in __init__
    bind = options.pop('bind', None) or db.engine
  File "c:\users\fb\appdata\local\programs\python\python37\lib\site-packages\flask_sqlalchemy\__init__.py", line 998, in engine
    return self.get_engine()
  File "c:\users\fb\appdata\local\programs\python\python37\lib\site-packages\flask_sqlalchemy\__init__.py", line 1017, in get_engine
    return connector.get_engine()
  File "c:\users\fb\appdata\local\programs\python\python37\lib\site-packages\flask_sqlalchemy\__init__.py", line 594, in get_engine
    self._engine = rv = self._sa.create_engine(sa_url, options)
  File "c:\users\fb\appdata\local\programs\python\python37\lib\site-packages\flask_sqlalchemy\__init__.py", line 1027, in create_engine
    return sqlalchemy.create_engine(sa_url, **engine_opts)
  File "<string>", line 2, in create_engine
  File "c:\users\fb\appdata\local\programs\python\python37\lib\site-packages\sqlalchemy\util\deprecations.py", line 298, in warned
    return fn(*args, **kwargs)
  File "c:\users\fb\appdata\local\programs\python\python37\lib\site-packages\sqlalchemy\engine\create.py", line 548, in create_engine
    dbapi = dialect_cls.dbapi(**dbapi_args)
  File "c:\users\fb\appdata\local\programs\python\python37\lib\site-packages\sqlalchemy\dialects\mysql\mysqldb.py", line 167, in dbapi
    return __import__("MySQLdb")
ModuleNotFoundError: No module named 'MySQLdb'
2021-08-03 15:48:38,461 INFO: Strefi startup [in C:\xampp\htdocs\onely\app\__init__.py:90]
