2021-08-10 14:52:55,035 ERROR: Exception on /api/countries [GET] [in c:\users\fb\appdata\local\programs\python\python37\lib\site-packages\flask\app.py:1455]
Traceback (most recent call last):
  File "c:\users\fb\appdata\local\programs\python\python37\lib\site-packages\sqlalchemy\engine\base.py", line 1772, in _execute_context
    cursor, statement, parameters, context
  File "c:\users\fb\appdata\local\programs\python\python37\lib\site-packages\sqlalchemy\engine\default.py", line 717, in do_execute
    cursor.execute(statement, parameters)
  File "c:\users\fb\appdata\local\programs\python\python37\lib\site-packages\MySQLdb\cursors.py", line 206, in execute
    res = self._query(query)
  File "c:\users\fb\appdata\local\programs\python\python37\lib\site-packages\MySQLdb\cursors.py", line 319, in _query
    db.query(q)
  File "c:\users\fb\appdata\local\programs\python\python37\lib\site-packages\MySQLdb\connections.py", line 259, in query
    _mysql.connection.query(self, query)
MySQLdb._exceptions.ProgrammingError: (1146, "Table 'onely.countries' doesn't exist")

The above exception was the direct cause of the following exception:

Traceback (most recent call last):
  File "c:\users\fb\appdata\local\programs\python\python37\lib\site-packages\flask\app.py", line 2070, in wsgi_app
    response = self.full_dispatch_request()
  File "c:\users\fb\appdata\local\programs\python\python37\lib\site-packages\flask\app.py", line 1515, in full_dispatch_request
    rv = self.handle_user_exception(e)
  File "c:\users\fb\appdata\local\programs\python\python37\lib\site-packages\flask\app.py", line 1513, in full_dispatch_request
    rv = self.dispatch_request()
  File "c:\users\fb\appdata\local\programs\python\python37\lib\site-packages\flask\app.py", line 1499, in dispatch_request
    return self.ensure_sync(self.view_functions[rule.endpoint])(**req.view_args)
  File "C:\xampp\htdocs\onely\app\api\countries.py", line 12, in get_countries
    users = Countries.query.all()
  File "c:\users\fb\appdata\local\programs\python\python37\lib\site-packages\sqlalchemy\orm\query.py", line 2712, in all
    return self._iter().all()
  File "c:\users\fb\appdata\local\programs\python\python37\lib\site-packages\sqlalchemy\orm\query.py", line 2850, in _iter
    execution_options={"_sa_orm_load_options": self.load_options},
  File "c:\users\fb\appdata\local\programs\python\python37\lib\site-packages\sqlalchemy\orm\session.py", line 1689, in execute
    result = conn._execute_20(statement, params or {}, execution_options)
  File "c:\users\fb\appdata\local\programs\python\python37\lib\site-packages\sqlalchemy\engine\base.py", line 1583, in _execute_20
    return meth(self, args_10style, kwargs_10style, execution_options)
  File "c:\users\fb\appdata\local\programs\python\python37\lib\site-packages\sqlalchemy\sql\elements.py", line 324, in _execute_on_connection
    self, multiparams, params, execution_options
  File "c:\users\fb\appdata\local\programs\python\python37\lib\site-packages\sqlalchemy\engine\base.py", line 1462, in _execute_clauseelement
    cache_hit=cache_hit,
  File "c:\users\fb\appdata\local\programs\python\python37\lib\site-packages\sqlalchemy\engine\base.py", line 1815, in _execute_context
    e, statement, parameters, cursor, context
  File "c:\users\fb\appdata\local\programs\python\python37\lib\site-packages\sqlalchemy\engine\base.py", line 1996, in _handle_dbapi_exception
    sqlalchemy_exception, with_traceback=exc_info[2], from_=e
  File "c:\users\fb\appdata\local\programs\python\python37\lib\site-packages\sqlalchemy\util\compat.py", line 207, in raise_
    raise exception
  File "c:\users\fb\appdata\local\programs\python\python37\lib\site-packages\sqlalchemy\engine\base.py", line 1772, in _execute_context
    cursor, statement, parameters, context
  File "c:\users\fb\appdata\local\programs\python\python37\lib\site-packages\sqlalchemy\engine\default.py", line 717, in do_execute
    cursor.execute(statement, parameters)
  File "c:\users\fb\appdata\local\programs\python\python37\lib\site-packages\MySQLdb\cursors.py", line 206, in execute
    res = self._query(query)
  File "c:\users\fb\appdata\local\programs\python\python37\lib\site-packages\MySQLdb\cursors.py", line 319, in _query
    db.query(q)
  File "c:\users\fb\appdata\local\programs\python\python37\lib\site-packages\MySQLdb\connections.py", line 259, in query
    _mysql.connection.query(self, query)
sqlalchemy.exc.ProgrammingError: (MySQLdb._exceptions.ProgrammingError) (1146, "Table 'onely.countries' doesn't exist")
[SQL: SELECT countries.id AS countries_id, countries.name AS countries_name 
FROM countries]
(Background on this error at: https://sqlalche.me/e/14/f405)
2021-08-10 14:53:47,587 INFO: Strefi startup [in C:\xampp\htdocs\onely\app\__init__.py:90]
2021-08-10 14:55:34,837 INFO: Strefi startup [in C:\xampp\htdocs\onely\app\__init__.py:90]
2021-08-10 14:55:36,956 ERROR: Exception on /api/countries [GET] [in c:\users\fb\appdata\local\programs\python\python37\lib\site-packages\flask\app.py:1455]
Traceback (most recent call last):
  File "c:\users\fb\appdata\local\programs\python\python37\lib\site-packages\flask\app.py", line 2070, in wsgi_app
    response = self.full_dispatch_request()
  File "c:\users\fb\appdata\local\programs\python\python37\lib\site-packages\flask\app.py", line 1515, in full_dispatch_request
    rv = self.handle_user_exception(e)
  File "c:\users\fb\appdata\local\programs\python\python37\lib\site-packages\flask\app.py", line 1513, in full_dispatch_request
    rv = self.dispatch_request()
  File "c:\users\fb\appdata\local\programs\python\python37\lib\site-packages\flask\app.py", line 1499, in dispatch_request
    return self.ensure_sync(self.view_functions[rule.endpoint])(**req.view_args)
  File "C:\xampp\htdocs\onely\app\api\countries.py", line 13, in get_countries
    return jsonify(data)
NameError: name 'data' is not defined
2021-08-10 14:55:49,460 INFO: Strefi startup [in C:\xampp\htdocs\onely\app\__init__.py:90]
2021-08-10 14:55:51,394 ERROR: Exception on /api/countries [GET] [in c:\users\fb\appdata\local\programs\python\python37\lib\site-packages\flask\app.py:1455]
Traceback (most recent call last):
  File "c:\users\fb\appdata\local\programs\python\python37\lib\site-packages\flask\app.py", line 2070, in wsgi_app
    response = self.full_dispatch_request()
  File "c:\users\fb\appdata\local\programs\python\python37\lib\site-packages\flask\app.py", line 1515, in full_dispatch_request
    rv = self.handle_user_exception(e)
  File "c:\users\fb\appdata\local\programs\python\python37\lib\site-packages\flask\app.py", line 1513, in full_dispatch_request
    rv = self.dispatch_request()
  File "c:\users\fb\appdata\local\programs\python\python37\lib\site-packages\flask\app.py", line 1499, in dispatch_request
    return self.ensure_sync(self.view_functions[rule.endpoint])(**req.view_args)
  File "C:\xampp\htdocs\onely\app\api\countries.py", line 13, in get_countries
    return jsonify(users)
  File "c:\users\fb\appdata\local\programs\python\python37\lib\site-packages\flask\json\__init__.py", line 348, in jsonify
    f"{dumps(data, indent=indent, separators=separators)}\n",
  File "c:\users\fb\appdata\local\programs\python\python37\lib\site-packages\flask\json\__init__.py", line 129, in dumps
    rv = _json.dumps(obj, **kwargs)
  File "c:\users\fb\appdata\local\programs\python\python37\lib\json\__init__.py", line 238, in dumps
    **kw).encode(obj)
  File "c:\users\fb\appdata\local\programs\python\python37\lib\json\encoder.py", line 199, in encode
    chunks = self.iterencode(o, _one_shot=True)
  File "c:\users\fb\appdata\local\programs\python\python37\lib\json\encoder.py", line 257, in iterencode
    return _iterencode(o, 0)
  File "c:\users\fb\appdata\local\programs\python\python37\lib\site-packages\flask\json\__init__.py", line 56, in default
    return super().default(o)
  File "c:\users\fb\appdata\local\programs\python\python37\lib\json\encoder.py", line 179, in default
    raise TypeError(f'Object of type {o.__class__.__name__} '
TypeError: Object of type Countries is not JSON serializable
2021-08-10 14:59:33,829 INFO: Strefi startup [in C:\xampp\htdocs\onely\app\__init__.py:90]
